Workbook

Sheet Recipes
A1: id | B1: name | C1: category | D1: cuisine | E1: servings | F1: prep_min | G1: cook_min | H1: total_min | I1: photo_file | J1: photo_keywords | K1: photo_url | L1: ingredients | M1: ingredients_json | N1: kcal | O1: protein_g | P1: fat_g | Q1: carbs_g | R1: fiber_g | S1: net_carbs_g | T1: glycemic_index | U1: gi_category | V1: glycemic_load | W1: gl_category | X1: gi_note | Y1: gi_evidence | Z1: gi_measured_carb_share_pct | AA1: diet_tags | AB1: instructions | AC1: steps_json
A2: DB-0001 | B2: Spinach & Feta Egg White Omelet | C2: Breakfast | D2: Mediterranean | E2: 1 | F2: 5 | G2: 8 | H2: 13 | I2: spinach-and-feta-egg-white-omelet.jpg | J2: Spinach & Feta Egg White Omelet, healthy food photography, plated, natural light | L2: Egg whites — 150 g (5.3 oz) [5 egg whites] Spinach — 60 g (2.1 oz) Feta cheese — 30 g (1.1 oz) Extra-virgin olive oil — 5 g (0.2 oz) Green onions (scallions) — 10 g (0.4 oz) Black pepper — 1 g (0.0 oz) | M2: [{"ingredient_id": "egg_white", "name": "Egg whites", "grams": 150.0, "note": "5 egg whites"}, {"ingredient_id": "spinach", "name": "Spinach", "grams": 60.0, "note": ""}, {"ingredient_id": "feta", "name": "Feta cheese", "grams": 30.0, "note": ""}, {"ingredient_id": "olive_oil", "name": "Extra-virgin olive oil", "grams": 5.0, "note": ""}, {"ingredient_id": "green_onion", "name": "Green onions (scallions)", "grams": 10.0, "note": ""}, {"ingredient_id": "black_pepper", "name": "Black pepper", "grams": 1.0, "note": ""}] | N2: 221 | O2: 22.7 | P2: 11.9 | Q2: 5.8 | R2: 1.8 | S2: 4 | T2: 6 | U2: low | V2: 0.2 | W2: low | X2: Negligible carbohydrate (<5 g net/serving): GI has little practical meaning, glycemic load is what matters. | Y2: 0% of this dish's available carbohydrate comes from ingredients with a published, measured GI; the rest uses conventional placeholders (see Ingredients sheet) | Z2: 0 | AA2: vegetarian, gluten-free, nut-free, low-carb, quick | AB2: 1. Heat olive oil in a nonstick skillet over medium heat and wilt the spinach for 1 minute. 2. Pour in the egg whites, season with pepper, and cook undisturbed until the edges set. 3. Sprinkle feta and green onion over one half, fold the omelet over and cook 1 more minute. 4. Slide onto a plate and serve immediately. | AC2: ["Heat olive oil in a nonstick skillet over medium heat and wilt the spinach for 1 minute.", "Pour in the egg whites, season with pepper, and cook undisturbed until the edges set.", "Sprinkle feta and green onion over one half, fold the omelet over and cook 1 more minute.", "Slide onto a plate and serve immediately."]
A3: DB-0002 | B3: Veggie-Loaded Scrambled Eggs | C3: Breakfast | D3: American | E3: 2 | F3: 10 | G3: 10 | H3: 20 | I3: veggie-loaded-scrambled-eggs.jpg | J3: Veggie-Loaded Scrambled Eggs, healthy food photography, plated, natural light | L3: Egg, large (50 g each) — 200 g (7.1 oz) [4 large eggs] Bell pepper — 80 g (2.8 oz) Mushrooms (cremini/white) — 80 g (2.8 oz) Spinach — 50 g (1.8 oz) Yellow onion — 40 g (1.4 oz) Extra-virgin olive oil — 10 g (0.4 oz) Cheddar cheese — 30 g (1.1 oz) Salt — 1 g (0.0 oz) Black pepper — 1 g (0.0 oz) | M3: [{"ingredient_id": "egg", "name": "Egg, large (50 g each)", "grams": 200.0, "note": "4 large eggs"}, {"ingredient_id": "bell_pepper", "name": "Bell pepper", "grams": 80.0, "note": ""}, {"ingredient_id": "mushrooms", "name": "Mushrooms (cremini/white)", "grams": 80.0, "note": ""}, {"ingredient_id": "spinach", "name": "Spinach", "grams": 50.0, "note": ""}, {"ingredient_id": "onion", "name": "Yellow onion", "grams": 40.0, "note": ""}, {"ingredient_id": "olive_oil", "name": "Extra-virgin olive oil", "grams": 10.0, "note": ""}, {"ingredient_id": "cheddar", "name": "Cheddar cheese", "grams": 30.0, "note": ""}, {"ingredient_id": "salt", "name": "Salt", "grams": 1.0, "note": ""}, {"ingredient_id": "black_pepper", "name": "Black pepper", "grams": 1.0, "note": ""}] | N3: 284 | O3: 18.7 | P3: 19.8 | Q3: 7.7 | R3: 2.3 | S3: 5.4 | T3: 13 | U3: low | V3: 0.7 | W3: low | Y3: 0% of this dish's available carbohydrate comes from ingredients with a published, measured GI; the rest uses conventional placeholders (see Ingredients sheet) | Z3: 0 | AA3: vegetarian, gluten-free, nut-free, low-carb, quick | AB3: 1. Sauté onion, bell pepper and mushrooms in olive oil over medium heat for 5 minutes until soft. 2. Add spinach and stir until wilted. 3. Whisk eggs with salt and pepper, pour over the vegetables and stir gently until softly set. 4. Fold in the cheddar, remove from heat and serve. | AC3: ["Sauté onion, bell pepper and mushrooms in olive oil over medium heat for 5 minutes until soft.", "Add spinach and stir until wilted.", "Whisk eggs with salt and pepper, pour over the vegetables and stir gently until softly set.", "Fold in the cheddar, remove from heat and serve."]
A4: DB-0003 | B4: Avocado & Egg Sprouted-Grain Toast | C4: Breakfast | D4: American | E4: 1 | F4: 5 | G4: 6 | H4: 11 | I4: avocado-and-egg-sprouted-grain-toast.jpg | J4: Avocado & Egg Sprouted-Grain Toast, healthy food photography, plated, natural light | L4: Sprouted grain bread (Ezekiel-style) — 34 g (1.2 oz) [1 slice] Avocado — 70 g (2.5 oz) [half avocado] Egg, large (50 g each) — 50 g (1.8 oz) [1 large egg] Lemon juice — 5 g (0.2 oz) Red pepper flakes — 0.5 g (0.0 oz) Salt — 0.5 g (0.0 oz) | M4: [{"ingredient_id": "ezekiel_bread", "name": "Sprouted grain bread (Ezekiel-style)", "grams": 34.0, "note": "1 slice"}, {"ingredient_id": "avocado", "name": "Avocado", "grams": 70.0, "note": "half avocado"}, {"ingredient_id": "egg", "name": "Egg, large (50 g each)", "grams": 50.0, "note": "1 large egg"}, {"ingredient_id": "lemon_juice", "name": "Lemon juice", "grams": 5.0, "note": ""}, {"ingredient_id": "red_pepper_flakes", "name": "Red pepper flakes", "grams": 0.5, "note": ""}, {"ingredient_id": "salt", "name": "Salt", "grams": 0.5, "note": ""}] | N4: 266 | O4: 11.9 | P4: 15.9 | Q4: 21.9 | R4: 7.9 | S4: 14 | T4: 55 | U4: low | V4: 7.7 | W4: low | Y4: 85% of this dish's available carbohydrate comes from ingredients with a published, measured GI; the rest uses conventional placeholders (see Ingredients sheet) | Z4: 85 | AA4: vegetarian, gluten-free, dairy-free, nut-free, low-carb, high-fiber, quick | AB4: 1. Toast the bread until golden. 2. Mash the avocado with lemon juice and salt and spread over the toast. 3. Fry or poach the egg to your liking and set it on top. 4. Finish with red pepper flakes. | AC4: ["Toast the bread until golden.", "Mash the avocado with lemon juice and salt and spread over the toast.", "Fry or poach the egg to your liking and set it on top.", "Finish with red pepper flakes."]
A5: DB-0004 | B5: Greek Yogurt Berry Parfait with Walnuts | C5: Breakfast | D5: American | E5: 1 | F5: 5 | G5: 0 | H5: 5 | I5: greek-yogurt-berry-parfait-with-walnuts.jpg | J5: Greek Yogurt Berry Parfait with Walnuts, healthy food photography, plated, natural light | L5: Greek yogurt, plain 2% — 200 g (7.1 oz) Mixed berries, frozen — 80 g (2.8 oz) Walnuts — 20 g (0.7 oz) Chia seeds — 8 g (0.3 oz) Ground cinnamon — 1 g (0.0 oz) | M5: [{"ingredient_id": "greek_yogurt", "name": "Greek yogurt, plain 2%", "grams": 200.0, "note": ""}, {"ingredient_id": "mixed_berries", "name": "Mixed berries, frozen", "grams": 80.0, "note": ""}, {"ingredient_id": "walnuts", "name": "Walnuts", "grams": 20.0, "note": ""}, {"ingredient_id": "chia_seeds", "name": "Chia seeds", "grams": 8.0, "note": ""}, {"ingredient_id": "cinnamon", "name": "Ground cinnamon", "grams": 1.0, "note": ""}] | N5: 354 | O5: 25 | P5: 19.8 | Q5: 23.8 | R5: 7.8 | S5: 16 | T5: 22 | U5: low | V5: 3.5 | W5: low | Y5: 50% of this dish's available carbohydrate comes from ingredients with a published, measured GI; the rest uses conventional placeholders (see Ingredients sheet) | Z5: 50 | AA5: vegetarian, gluten-free, high-protein, high-fiber, no-cook, quick | AB5: 1. Spoon half the yogurt into a glass or bowl. 2. Layer half the berries and walnuts, then repeat with the remaining yogurt and toppings. 3. Sprinkle chia seeds and cinnamon on top and serve, or refrigerate up to 24 hours. | AC5: ["Spoon half the yogurt into a glass or bowl.", "Layer half the berries and walnuts, then repeat with the remaining yogurt and toppings.", "Sprinkle chia seeds and cinnamon on top and serve, or refrigerate up to 24 hours."]
A6: DB-0005 | B6: Overnight Steel-Cut Oats with Blueberries | C6: Breakfast | D6: American | E6: 2 | F6: 5 | G6: 0 | H6: 5 | I6: overnight-steel-cut-oats-with-blueberries.jpg | J6: Overnight Steel-Cut Oats with Blueberries, healthy food photography, plated, natural light | L6: Steel-cut oats, dry — 70 g (2.5 oz) Almond milk, unsweetened — 300 g (10.6 oz) Chia seeds — 15 g (0.5 oz) Blueberries — 100 g (3.5 oz) Almonds — 20 g (0.7 oz) Ground cinnamon — 2 g (0.1 oz) Vanilla extract — 3 g (0.1 oz) | M6: [{"ingredient_id": "steel_cut_oats", "name": "Steel-cut oats, dry", "grams": 70.0, "note": ""}, {"ingredient_id": "almond_milk", "name": "Almond milk, unsweetened", "grams": 300.0, "note": ""}, {"ingredient_id": "chia_seeds", "name": "Chia seeds", "grams": 15.0, "note": ""}, {"ingredient_id": "blueberries", "name": "Blueberries", "grams": 100.0, "note": ""}, {"ingredient_id": "almonds", "name": "Almonds", "grams": 20.0, "note": ""}, {"ingredient_id": "cinnamon", "name": "Ground cinnamon", "grams": 2.0, "note": ""}, {"ingredient_id": "vanilla_extract", "name": "Vanilla extract", "grams": 3.0, "note": ""}] | N6: 283 | O6: 9.2 | P6: 11.6 | Q6: 38 | R6: 9 | S6: 28.9 | T6: 49 | U6: low | V6: 14.2 | W6: medium | Y6: 90% of this dish's available carbohydrate comes from ingredients with a published, measured GI; the rest uses conventional placeholders (see Ingredients sheet) | Z6: 90 | AA6: vegan, dairy-free, high-fiber, no-cook, make-ahead | AB6: 1. Combine oats, almond milk, chia seeds, cinnamon and vanilla in a jar and stir well. 2. Refrigerate overnight (at least 8 hours) so the oats soften without cooking, which keeps the GI lower. 3. In the morning stir, divide into two bowls and top with blueberries and sliced almonds. | AC6: ["Combine oats, almond milk, chia seeds, cinnamon and vanilla in a jar and stir well.", "Refrigerate overnight (at least 8 hours) so the oats soften without cooking, which keeps the GI lower.", "In the morning stir, divide into two bowls and top with blueberries and sliced almonds."]
A7: DB-0006 | B7: Chia Seed Pudding with Raspberries | C7: Breakfast | D7: American | E7: 2 | F7: 5 | G7: 0 | H7: 5 | I7: chia-seed-pudding-with-raspberries.jpg | J7: Chia Seed Pudding with Raspberries, healthy food photography, plated, natural light | L7: Chia seeds — 40 g (1.4 oz) Almond milk, unsweetened — 300 g (10.6 oz) Raspberries — 100 g (3.5 oz) Vanilla extract — 3 g (0.1 oz) Monk fruit/erythritol sweetener — 5 g (0.2 oz) Almonds — 15 g (0.5 oz) | M7: [{"ingredient_id": "chia_seeds", "name": "Chia seeds", "grams": 40.0, "note": ""}, {"ingredient_id": "almond_milk", "name": "Almond milk, unsweetened", "grams": 300.0, "note": ""}, {"ingredient_id": "raspberries", "name": "Raspberries", "grams": 100.0, "note": ""}, {"ingredient_id": "vanilla_extract", "name": "Vanilla extract", "grams": 3.0, "note": ""}, {"ingredient_id": "monk_fruit_sweetener", "name": "Monk fruit/erythritol sweetener", "grams": 5.0, "note": ""}, {"ingredient_id": "almonds", "name": "Almonds", "grams": 15.0, "note": ""}] | N7: 193 | O7: 6.5 | P7: 12.1 | Q7: 17.1 | R7: 11 | S7: 6.2 | T7: 24 | U7: low | V7: 1.5 | W7: low | Y7: 0% of this dish's available carbohydrate comes from ingredients with a published, measured GI; the rest uses conventional placeholders (see Ingredients sheet) | Z7: 0 | AA7: vegan, gluten-free, dairy-free, low-carb, high-fiber, no-cook, make-ahead | AB7: 1. Whisk chia seeds, almond milk, vanilla and sweetener in a bowl. 2. Let stand 10 minutes, whisk again to break up clumps, then refrigerate at least 4 hours or overnight. 3. Spoon into bowls and top with raspberries and sliced almonds. | AC7: ["Whisk chia seeds, almond milk, vanilla and sweetener in a bowl.", "Let stand 10 minutes, whisk again to break up clumps, then refrigerate at least 4 hours or overnight.", "Spoon into bowls and top with raspberries and sliced almonds."]
A8: DB-0007 | B8: Cottage Cheese Bowl with Peaches & Pecans | C8: Breakfast | D8: American | E8: 1 | F8: 5 | G8: 0 | H8: 5 | I8: cottage-cheese-bowl-with-peaches-and-pecans.jpg | J8: Cottage Cheese Bowl with Peaches & Pecans, healthy food photography, plated, natural light | L8: Cottage cheese, low-fat — 200 g (7.1 oz) Peach — 120 g (4.2 oz) [1 medium peach] Pecans — 20 g (0.7 oz) Ground cinnamon — 1 g (0.0 oz) Ground flaxseed — 8 g (0.3 oz) | M8: [{"ingredient_id": "cottage_cheese", "name": "Cottage cheese, low-fat", "grams": 200.0, "note": ""}, {"ingredient_id": "peach", "name": "Peach", "grams": 120.0, "note": "1 medium peach"}, {"ingredient_id": "pecans", "name": "Pecans", "grams": 20.0, "note": ""}, {"ingredient_id": "cinnamon", "name": "Ground cinnamon", "grams": 1.0, "note": ""}, {"ingredient_id": "flaxseed", "name": "Ground flaxseed", "grams": 8.0, "note": ""}] | N8: 398 | O8: 26.4 | P8: 22.7 | Q8: 25.9 | R8: 6.4 | S8: 19.5 | T8: 33 | U8: low | V8: 6.4 | W8: low | Y8: 49% of this dish's available carbohydrate comes from ingredients with a published, measured GI; the rest uses conventional placeholders (see Ingredients sheet) | Z8: 49 | AA8: vegetarian, gluten-free, high-protein, no-cook, quick | AB8: 1. Spoon the cottage cheese into a bowl. 2. Slice the peach and arrange on top. 3. Sprinkle with chopped pecans, ground flaxseed and cinnamon. | AC8: ["Spoon the cottage cheese into a bowl.", "Slice the peach and arrange on top.", "Sprinkle with chopped pecans, ground flaxseed and cinnamon."]
A9: DB-0008 | B9: Southwest Breakfast Burrito | C9: Breakfast | D9: Tex-Mex | E9: 2 | F9: 10 | G9: 12 | H9: 22 | I9: southwest-breakfast-burrito.jpg | J9: Southwest Breakfast Burrito, healthy food photography, plated, natural light | L9: Low-carb high-fiber tortilla — 84 g (3.0 oz) [2 tortillas] Egg, large (50 g each) — 200 g (7.1 oz) [4 large eggs] Black beans, cooked — 80 g (2.8 oz) Bell pepper — 60 g (2.1 oz) Yellow onion — 30 g (1.1 oz) Pepper jack cheese — 40 g (1.4 oz) Salsa, no sugar added — 60 g (2.1 oz) Avocado — 60 g (2.1 oz) Extra-virgin olive oil — 8 g (0.3 oz) Ground cumin — 1 g (0.0 oz) | M9: [{"ingredient_id": "low_carb_tortilla", "name": "Low-carb high-fiber tortilla", "grams": 84.0, "note": "2 tortillas"}, {"ingredient_id": "egg", "name": "Egg, large (50 g each)", "grams": 200.0, "note": "4 large eggs"}, {"ingredient_id": "black_beans", "name": "Black beans, cooked", "grams": 80.0, "note": ""}, {"ingredient_id": "bell_pepper", "name": "Bell pepper", "grams": 60.0, "note": ""}, {"ingredient_id": "onion", "name": "Yellow onion", "grams": 30.0, "note": ""}, {"ingredient_id": "pepper_jack", "name": "Pepper jack cheese", "grams": 40.0, "note": ""}, {"ingredient_id": "salsa", "name": "Salsa, no sugar added", "grams": 60.0, "note": ""}, {"ingredient_id": "avocado", "name": "Avocado", "grams": 60.0, "note": ""}, {"ingredient_id": "olive_oil", "name": "Extra-virgin olive oil", "grams": 8.0, "note": ""}, {"ingredient_id": "cumin", "name": "Ground cumin", "grams": 1.0, "note": ""}] | N9: 488 | O9: 27.6 | P9: 27.8 | Q9: 35.3 | R9: 17.4 | S9: 18 | T9: 26 | U9: low | V9: 4.7 | W9: low | Y9: 33% of this dish's available carbohydrate comes from ingredients with a published, measured GI; the rest uses conventional placeholders (see Ingredients sheet) | Z9: 33 | AA9: vegetarian, nut-free, high-protein, high-fiber | AB9: 1. Sauté onion and bell pepper in olive oil for 4 minutes, add black beans and cumin and warm through. 2. Whisk the eggs, pour into the pan and scramble until just set. 3. Warm the tortillas, fill with the egg mixture, cheese, avocado and salsa. 4. Roll tightly, folding in the sides, and cut in half. | AC9: ["Sauté onion and bell pepper in olive oil for 4 minutes, add black beans and cumin and warm through.", "Whisk the eggs, pour into the pan and scramble until just set.", "Warm the tortillas, fill with the egg mixture, cheese, avocado and salsa.", "Roll tightly, folding in the sides, and cut in half."]
A10: DB-0009 | B10: Turkey Sausage & Kale Frittata | C10: Breakfast | D10: American | E10: 4 | F10: 10 | G10: 25 | H10: 35 | I10: turkey-sausage-and-kale-frittata.jpg | J10: Turkey Sausage & Kale Frittata, healthy food photography, plated, natural light | L10: Egg, large (50 g each) — 400 g (14.1 oz) [8 large eggs] Turkey sausage — 200 g (7.1 oz) Kale — 100 g (3.5 oz) Yellow onion — 60 g (2.1 oz) Mozzarella, part-skim — 60 g (2.1 oz) Extra-virgin olive oil — 10 g (0.4 oz) Garlic — 5 g (0.2 oz) Salt — 2 g (0.1 oz) Black pepper — 1 g (0.0 oz) | M10: [{"ingredient_id": "egg", "name": "Egg, large (50 g each)", "grams": 400.0, "note": "8 large eggs"}, {"ingredient_id": "turkey_sausage", "name": "Turkey sausage", "grams": 200.0, "note": ""}, {"ingredient_id": "kale", "name": "Kale", "grams": 100.0, "note": ""}, {"ingredient_id": "onion", "name": "Yellow onion", "grams": 60.0, "note": ""}, {"ingredient_id": "mozzarella", "name": "Mozzarella, part-skim", "grams": 60.0, "note": ""}, {"ingredient_id": "olive_oil", "name": "Extra-virgin olive oil", "grams": 10.0, "note": ""}, {"ingredient_id": "garlic", "name": "Garlic", "grams": 5.0, "note": ""}, {"ingredient_id": "salt", "name": "Salt", "grams": 2.0, "note": ""}, {"ingredient_id": "black_pepper", "name": "Black pepper", "grams": 1.0, "note": ""}] | N10: 301 | O10: 25 | P10: 19.7 | Q10: 6.3 | R10: 1.2 | S10: 5.1 | T10: 10 | U10: low | V10: 0.5 | W10: low | Y10: 0% of this dish's available carbohydrate comes from ingredients with a published, measured GI; the rest uses conventional placeholders (see Ingredients sheet) | Z10: 0 | AA10: gluten-free, nut-free, low-carb, high-protein, make-ahead | AB10: 1. Preheat oven to 375°F. Brown crumbled turkey sausage in an ovenproof skillet, then remove. 2. Sauté onion and garlic in olive oil, add kale and cook until wilted. Return sausage to the pan. 3. Whisk eggs with salt and pepper, pour over the filling and scatter mozzarella on top. 4. Cook 2 minutes on the stove, then bake 15–18 minutes until set. Cool 5 minutes before slicing. | AC10: ["Preheat oven to 375°F. Brown crumbled turkey sausage in an ovenproof skillet, then remove.", "Sauté onion and garlic in olive oil, add kale and cook until wilted. Return sausage to the pan.", "Whisk eggs with salt and pepper, pour over the filling and scatter mozzarella on top.", "Cook 2 minutes on the stove, then bake 15–18 minutes until set. Cool 5 minutes before slicing."]
A11: DB-0010 | B11: Almond Flour Blueberry Pancakes | C11: Breakfast | D11: American | E11: 2 | F11: 10 | G11: 12 | H11: 22 | I11: almond-flour-blueberry-pancakes.jpg | J11: Almond Flour Blueberry Pancakes, healthy food photography, plated, natural light | L11: Almond flour — 100 g (3.5 oz) Egg, large (50 g each) — 100 g (3.5 oz) [2 large eggs] Almond milk, unsweetened — 60 g (2.1 oz) Baking powder — 4 g (0.1 oz) Vanilla extract — 3 g (0.1 oz) Monk fruit/erythritol sweetener — 8 g (0.3 oz) Blueberries — 80 g (2.8 oz) Coconut oil — 10 g (0.4 oz) | M11: [{"ingredient_id": "almond_flour", "name": "Almond flour", "grams": 100.0, "note": ""}, {"ingredient_id": "egg", "name": "Egg, large (50 g each)", "grams": 100.0, "note": "2 large eggs"}, {"ingredient_id": "almond_milk", "name": "Almond milk, unsweetened", "grams": 60.0, "note": ""}, {"ingredient_id": "baking_powder", "name": "Baking powder", "grams": 4.0, "note": ""}, {"ingredient_id": "vanilla_extract", "name": "Vanilla extract", "grams": 3.0, "note": ""}, {"ingredient_id": "monk_fruit_sweetener", "name": "Monk fruit/erythritol sweetener", "grams": 8.0, "note": ""}, {"ingredient_id": "blueberries", "name": "Blueberries", "grams": 80.0, "note": ""}, {"ingredient_id": "coconut_oil", "name": "Coconut oil", "grams": 10.0, "note": ""}] | N11: 442 | O11: 17.3 | P11: 35.2 | Q11: 17.6 | R11: 7 | S11: 10.6 | T11: 31 | U11: low | V11: 3.3 | W11: low | Y11: 46% of this dish's available carbohydrate comes from ingredients with a published, measured GI; the rest uses conventional placeholders (see Ingredients sheet) | Z11: 46 | AA11: vegetarian, gluten-free, dairy-free, low-carb | AB11: 1. Whisk eggs, almond milk, vanilla and sweetener, then stir in almond flour and baking powder to a thick batter. 2. Fold in the blueberries. 3. Cook 1/4-cup portions in coconut oil over medium-low heat, 3 minutes per side, flipping carefully. 4. Serve warm with extra berries if desired. | AC11: ["Whisk eggs, almond milk, vanilla and sweetener, then stir in almond flour and baking powder to a thick batter.", "Fold in the blueberries.", "Cook 1/4-cup portions in coconut oil over medium-low heat, 3 minutes per side, flipping carefully.", "Serve warm with extra berries if desired."]
A12: DB-0011 | B12: Shakshuka with Feta | C12: Breakfast | D12: Middle Eastern | E12: 2 | F12: 10 | G12: 25 | H12: 35 | I12: shakshuka-with-feta.jpg | J12: Shakshuka with Feta, healthy food photography, plated, natural light | L12: Egg, large (50 g each) — 200 g (7.1 oz) [4 large eggs] Crushed tomatoes, canned — 400 g (14.1 oz) Bell pepper — 120 g (4.2 oz) Yellow onion — 80 g (2.8 oz) Garlic — 8 g (0.3 oz) Extra-virgin olive oil — 15 g (0.5 oz) Ground cumin — 2 g (0.1 oz) Smoked paprika — 2 g (0.1 oz) Feta cheese — 40 g (1.4 oz) Fresh parsley — 10 g (0.4 oz) Salt — 2 g (0.1 oz) | M12: [{"ingredient_id": "egg", "name": "Egg, large (50 g each)", "grams": 200.0, "note": "4 large eggs"}, {"ingredient_id": "crushed_tomatoes", "name": "Crushed tomatoes, canned", "grams": 400.0, "note": ""}, {"ingredient_id": "bell_pepper", "name": "Bell pepper", "grams": 120.0, "note": ""}, {"ingredient_id": "onion", "name": "Yellow onion", "grams": 80.0, "note": ""}, {"ingredient_id": "garlic", "name": "Garlic", "grams": 8.0, "note": ""}, {"ingredient_id": "olive_oil", "name": "Extra-virgin olive oil", "grams": 15.0, "note": ""}, {"ingredient_id": "cumin", "name": "Ground cumin", "grams": 2.0, "note": ""}, {"ingredient_id": "smoked_paprika", "name": "Smoked paprika", "grams": 2.0, "note": ""}, {"ingredient_id": "feta", "name": "Feta cheese", "grams": 40.0, "note": ""}, {"ingredient_id": "parsley", "name": "Fresh parsley", "grams": 10.0, "note": ""}, {"ingredient_id": "salt", "name": "Salt", "grams": 2.0, "note": ""}] | N12: 375 | O12: 20.4 | P12: 22.4 | Q12: 25.4 | R12: 6.4 | S12: 19 | T12: 26 | U12: low | V12: 4.9 | W12: low | Y12: 0% of this dish's available carbohydrate comes from ingredients with a published, measured GI; the rest uses conventional placeholders (see Ingredients sheet) | Z12: 0 | AA12: vegetarian, gluten-free, nut-free, one-pan | AB12: 1. Sauté onion and bell pepper in olive oil over medium heat for 7 minutes, add garlic, cumin and paprika and cook 1 minute. 2. Pour in crushed tomatoes, season with salt and simmer 10 minutes until slightly thickened. 3. Make four wells, crack an egg into each, cover and cook 6–8 minutes until whites are set. 4. Top with crumbled feta and parsley and serve straight from the pan. | AC12: ["Sauté onion and bell pepper in olive oil over medium heat for 7 minutes, add garlic, cumin and paprika and cook 1 minute.", "Pour in crushed tomatoes, season with salt and simmer 10 minutes until slightly thickened.", "Make four wells, crack an egg into each, cover and cook 6–8 minutes until whites are set.", "Top with crumbled feta and parsley and serve straight from the pan."]
A13: DB-0012 | B13: Smoked Salmon & Cream Cheese Egg Wrap | C13: Breakfast | D13: American | E13: 1 | F13: 5 | G13: 5 | H13: 10 | I13: smoked-salmon-and-cream-cheese-egg-wrap.jpg | J13: Smoked Salmon & Cream Cheese Egg Wrap, healthy food photography, plated, natural light | L13: Egg, large (50 g each) — 100 g (3.5 oz) [2 large eggs] Smoked salmon — 60 g (2.1 oz) Cream cheese — 20 g (0.7 oz) Cucumber — 40 g (1.4 oz) Fresh dill — 3 g (0.1 oz) Capers — 5 g (0.2 oz) Extra-virgin olive oil — 4 g (0.1 oz) | M13: [{"ingredient_id": "egg", "name": "Egg, large (50 g each)", "grams": 100.0, "note": "2 large eggs"}, {"ingredient_id": "smoked_salmon", "name": "Smoked salmon", "grams": 60.0, "note": ""}, {"ingredient_id": "cream_cheese", "name": "Cream cheese", "grams": 20.0, "note": ""}, {"ingredient_id": "cucumber", "name": "Cucumber", "grams": 40.0, "note": ""}, {"ingredient_id": "dill", "name": "Fresh dill", "grams": 3.0, "note": ""}, {"ingredient_id": "capers", "name": "Capers", "grams": 5.0, "note": ""}, {"ingredient_id": "olive_oil", "name": "Extra-virgin olive oil", "grams": 4.0, "note": ""}] | N13: 325 | O13: 25.1 | P13: 23 | Q13: 3.4 | R13: 0.4 | S13: 3 | T13: 7 | U13: low | V13: 0.2 | W13: low | X13: Negligible carbohydrate (<5 g net/serving): GI has little practical meaning, glycemic load is what matters. | Y13: 0% of this dish's available carbohydrate comes from ingredients with a published, measured GI; the rest uses conventional placeholders (see Ingredients sheet) | Z13: 0 | AA13: pescatarian, gluten-free, nut-free, low-carb, high-protein, quick | AB13: 1. Whisk eggs and cook in a lightly oiled nonstick pan as one thin round crepe-like layer, about 2 minutes. 2. Slide the egg wrap onto a plate and spread with cream cheese. 3. Layer smoked salmon, thin cucumber slices, capers and dill. 4. Roll up tightly and slice in half. | AC13: ["Whisk eggs and cook in a lightly oiled nonstick pan as one thin round crepe-like layer, about 2 minutes.", "Slide the egg wrap onto a plate and spread with cream cheese.", "Layer smoked salmon, thin cucumber slices, capers and dill.", "Roll up tightly and slice in half."]
A14: DB-0013 | B14: Peanut Butter Protein Smoothie | C14: Breakfast | D14: American | E14: 1 | F14: 5 | G14: 0 | H14: 5 | I14: peanut-butter-protein-smoothie.jpg | J14: Peanut Butter Protein Smoothie, healthy food photography, plated, natural light | L14: Almond milk, unsweetened — 300 g (10.6 oz) Whey protein powder, unsweetened — 30 g (1.1 oz) Peanut butter, natural — 16 g (0.6 oz) Spinach — 40 g (1.4 oz) Banana (small amount) — 50 g (1.8 oz) [half small banana] Chia seeds — 8 g (0.3 oz) Water / ice — 50 g (1.8 oz) [ice] | M14: [{"ingredient_id": "almond_milk", "name": "Almond milk, unsweetened", "grams": 300.0, "note": ""}, {"ingredient_id": "whey_protein", "name": "Whey protein powder, unsweetened", "grams": 30.0, "note": ""}, {"ingredient_id": "peanut_butter", "name": "Peanut butter, natural", "grams": 16.0, "note": ""}, {"ingredient_id": "spinach", "name": "Spinach", "grams": 40.0, "note": ""}, {"ingredient_id": "banana", "name": "Banana (small amount)", "grams": 50.0, "note": "half small banana"}, {"ingredient_id": "chia_seeds", "name": "Chia seeds", "grams": 8.0, "note": ""}, {"ingredient_id": "water", "name": "Water / ice", "grams": 50.0, "note": "ice"}] | N14: 346 | O14: 32.3 | P14: 15.9 | Q14: 23.7 | R14: 6.2 | S14: 17.5 | T14: 39 | U14: low | V14: 6.8 | W14: low | Y14: 70% of this dish's available carbohydrate comes from ingredients with a published, measured GI; the rest uses conventional placeholders (see Ingredients sheet) | Z14: 70 | AA14: vegetarian, gluten-free, high-protein, no-cook, quick | AB14: 1. Add almond milk, protein powder, peanut butter, spinach, banana and chia seeds to a blender. 2. Add a handful of ice and blend on high until completely smooth. 3. Pour into a glass and drink right away. | AC14: ["Add almond milk, protein powder, peanut butter, spinach, banana and chia seeds to a blender.", "Add a handful of ice and blend on high until completely smooth.", "Pour into a glass and drink right away."]
A15: DB-0014 | B15: Green Power Smoothie | C15: Breakfast | D15: American | E15: 1 | F15: 5 | G15: 0 | H15: 5 | I15: green-power-smoothie.jpg | J15: Green Power Smoothie, healthy food photography, plated, natural light | L15: Spinach — 60 g (2.1 oz) Kale — 30 g (1.1 oz) Avocado — 50 g (1.8 oz) Cucumber — 80 g (2.8 oz) Greek yogurt, plain 2% — 120 g (4.2 oz) Lemon juice — 10 g (0.4 oz) Fresh ginger — 5 g (0.2 oz) Water / ice — 150 g (5.3 oz) [water + ice] Hemp seeds — 10 g (0.4 oz) | M15: [{"ingredient_id": "spinach", "name": "Spinach", "grams": 60.0, "note": ""}, {"ingredient_id": "kale", "name": "Kale", "grams": 30.0, "note": ""}, {"ingredient_id": "avocado", "name": "Avocado", "grams": 50.0, "note": ""}, {"ingredient_id": "cucumber", "name": "Cucumber", "grams": 80.0, "note": ""}, {"ingredient_id": "greek_yogurt", "name": "Greek yogurt, plain 2%", "grams": 120.0, "note": ""}, {"ingredient_id": "lemon_juice", "name": "Lemon juice", "grams": 10.0, "note": ""}, {"ingredient_id": "ginger", "name": "Fresh ginger", "grams": 5.0, "note": ""}, {"ingredient_id": "water", "name": "Water / ice", "grams": 150.0, "note": "water + ice"}, {"ingredient_id": "hemp_seeds", "name": "Hemp seeds", "grams": 10.0, "note": ""}] | N15: 270 | O15: 19.9 | P15: 15.4 | Q15: 19.2 | R15: 6.7 | S15: 12.5 | T15: 14 | U15: low | V15: 1.8 | W15: low | Y15: 38% of this dish's available carbohydrate comes from ingredients with a published, measured GI; the rest uses conventional placeholders (see Ingredients sheet) | Z15: 38 | AA15: vegetarian, gluten-free, nut-free, low-carb, no-cook, quick | AB15: 1. Combine all ingredients in a blender. 2. Blend on high for 45–60 seconds until silky. 3. Adjust thickness with water and serve cold. | AC15: ["Combine all ingredients in a blender.", "Blend on high for 45–60 seconds until silky.", "Adjust thickness with water and serve cold."]
A16: DB-0015 | B16: Mushroom & Swiss Omelet | C16: Breakfast | D16: American | E16: 1 | F16: 5 | G16: 10 | H16: 15 | I16: mushroom-and-swiss-omelet.jpg | J16: Mushroom & Swiss Omelet, healthy food photography, plated, natural light | L16: Egg, large (50 g each) — 150 g (5.3 oz) [3 large eggs] Mushrooms (cremini/white) — 80 g (2.8 oz) Swiss cheese — 30 g (1.1 oz) Butter — 8 g (0.3 oz) Fresh chives — 3 g (0.1 oz) Salt — 1 g (0.0 oz) Black pepper — 1 g (0.0 oz) | M16: [{"ingredient_id": "egg", "name": "Egg, large (50 g each)", "grams": 150.0, "note": "3 large eggs"}, {"ingredient_id": "mushrooms", "name": "Mushrooms (cremini/white)", "grams": 80.0, "note": ""}, {"ingredient_id": "swiss_cheese", "name": "Swiss cheese", "grams": 30.0, "note": ""}, {"ingredient_id": "butter", "name": "Butter", "grams": 8.0, "note": ""}, {"ingredient_id": "chives", "name": "Fresh chives", "grams": 3.0, "note": ""}, {"ingredient_id": "salt", "name": "Salt", "grams": 1.0, "note": ""}, {"ingredient_id": "black_pepper", "name": "Black pepper", "grams": 1.0, "note": ""}] | N16: 407 | O16: 29.8 | P16: 29.4 | Q16: 4.9 | R16: 1.1 | S16: 3.8 | T16: 9 | U16: low | V16: 0.3 | W16: low | X16: Negligible carbohydrate (<5 g net/serving): GI has little practical meaning, glycemic load is what matters. | Y16: 0% of this dish's available carbohydrate comes from ingredients with a published, measured GI; the rest uses conventional placeholders (see Ingredients sheet) | Z16: 0 | AA16: vegetarian, gluten-free, nut-free, low-carb, high-protein, quick | AB16: 1. Sauté mushrooms in half the butter until browned, about 5 minutes; set aside. 2. Whisk eggs with salt and pepper, melt the remaining butter and pour in the eggs, tilting the pan as they set. 3. Add mushrooms and Swiss cheese to one side, fold and cook 1 minute more. 4. Garnish with chives. | AC16: ["Sauté mushrooms in half the butter until browned, about 5 minutes; set aside.", "Whisk eggs with salt and pepper, melt the remaining butter and pour in the eggs, tilting the pan as they set.", "Add mushrooms and Swiss cheese to one side, fold and cook 1 minute more.", "Garnish with chives."]
A17: DB-0016 | B17: Tomato, Basil & Mozzarella Egg Bake | C17: Breakfast | D17: Italian | E17: 4 | F17: 10 | G17: 30 | H17: 40 | I17: tomato-basil-and-mozzarella-egg-bake.jpg | J17: Tomato, Basil & Mozzarella Egg Bake, healthy food photography, plated, natural light | L17: Egg, large (50 g each) — 400 g (14.1 oz) [8 large eggs] Cherry tomatoes — 200 g (7.1 oz) Mozzarella, part-skim — 100 g (3.5 oz) Fresh basil — 15 g (0.5 oz) Milk, 2% — 60 g (2.1 oz) Garlic — 5 g (0.2 oz) Extra-virgin olive oil — 10 g (0.4 oz) Salt — 2 g (0.1 oz) Black pepper — 1 g (0.0 oz) | M17: [{"ingredient_id": "egg", "name": "Egg, large (50 g each)", "grams": 400.0, "note": "8 large eggs"}, {"ingredient_id": "cherry_tomato", "name": "Cherry tomatoes", "grams": 200.0, "note": ""}, {"ingredient_id": "mozzarella", "name": "Mozzarella, part-skim", "grams": 100.0, "note": ""}, {"ingredient_id": "basil", "name": "Fresh basil", "grams": 15.0, "note": ""}, {"ingredient_id": "milk", "name": "Milk, 2%", "grams": 60.0, "note": ""}, {"ingredient_id": "garlic", "name": "Garlic", "grams": 5.0, "note": ""}, {"ingredient_id": "olive_oil", "name": "Extra-virgin olive oil", "grams": 10.0, "note": ""}, {"ingredient_id": "salt", "name": "Salt", "grams": 2.0, "note": ""}, {"ingredient_id": "black_pepper", "name": "Black pepper", "grams": 1.0, "note": ""}] | N17: 248 | O17: 19.8 | P17: 16.4 | Q17: 4.8 | R17: 0.7 | S17: 4 | T17: 13 | U17: low | V17: 0.5 | W17: low | X17: Negligible carbohydrate (<5 g net/serving): GI has little practical meaning, glycemic load is what matters. | Y17: 18% of this dish's available carbohydrate comes from ingredients with a published, measured GI; the rest uses conventional placeholders (see Ingredients sheet) | Z17: 18 | AA17: vegetarian, gluten-free, nut-free, low-carb, make-ahead | AB17: 1. Preheat oven to 375°F and oil a 9-inch baking dish. 2. Whisk eggs, milk, garlic, salt and pepper; pour into the dish. 3. Scatter halved cherry tomatoes and torn mozzarella over the top. 4. Bake 25–30 minutes until puffed and set; top with torn basil before serving. | AC17: ["Preheat oven to 375°F and oil a 9-inch baking dish.", "Whisk eggs, milk, garlic, salt and pepper; pour into the dish.", "Scatter halved cherry tomatoes and torn mozzarella over the top.", "Bake 25–30 minutes until puffed and set; top with torn basil before serving."]
A18: DB-0017 | B18: Egg Muffin Cups with Broccoli & Cheddar | C18: Breakfast | D18: American | E18: 6 | F18: 10 | G18: 22 | H18: 32 | I18: egg-muffin-cups-with-broccoli-and-cheddar.jpg | J18: Egg Muffin Cups with Broccoli & Cheddar, healthy food photography, plated, natural light | L18: Egg, large (50 g each) — 500 g (17.6 oz) [10 large eggs] Broccoli — 200 g (7.1 oz) Cheddar cheese — 90 g (3.2 oz) Green onions (scallions) — 30 g (1.1 oz) Milk, 2% — 60 g (2.1 oz) Salt — 2 g (0.1 oz) Black pepper — 1 g (0.0 oz) Extra-virgin olive oil — 5 g (0.2 oz) | M18: [{"ingredient_id": "egg", "name": "Egg, large (50 g each)", "grams": 500.0, "note": "10 large eggs"}, {"ingredient_id": "broccoli", "name": "Broccoli", "grams": 200.0, "note": ""}, {"ingredient_id": "cheddar", "name": "Cheddar cheese", "grams": 90.0, "note": ""}, {"ingredient_id": "green_onion", "name": "Green onions (scallions)", "grams": 30.0, "note": ""}, {"ingredient_id": "milk", "name": "Milk, 2%", "grams": 60.0, "note": ""}, {"ingredient_id": "salt", "name": "Salt", "grams": 2.0, "note": ""}, {"ingredient_id": "black_pepper", "name": "Black pepper", "grams": 1.0, "note": ""}, {"ingredient_id": "olive_oil", "name": "Extra-virgin olive oil", "grams": 5.0, "note": ""}] | N18: 205 | O18: 15.3 | P18: 14 | Q18: 3.9 | R18: 1 | S18: 2.9 | T18: 13 | U18: low | V18: 0.4 | W18: low | X18: Negligible carbohydrate (<5 g net/serving): GI has little practical meaning, glycemic load is what matters. | Y18: 17% of this dish's available carbohydrate comes from ingredients with a published, measured GI; the rest uses conventional placeholders (see Ingredients sheet) | Z18: 17 | AA18: vegetarian, gluten-free, nut-free, low-carb, make-ahead, meal-prep | AB18: 1. Preheat oven to 350°F and oil a 12-cup muffin tin. 2. Steam finely chopped broccoli 2 minutes and divide among the cups with cheddar and green onion. 3. Whisk eggs with milk, salt and pepper and pour over the fillings. 4. Bake 20–22 minutes until set. Cool, then refrigerate up to 5 days or freeze. | AC18: ["Preheat oven to 350°F and oil a 12-cup muffin tin.", "Steam finely chopped broccoli 2 minutes and divide among the cups with cheddar and green onion.", "Whisk eggs with milk, salt and pepper and pour over the fillings.", "Bake 20–22 minutes until set. Cool, then refrigerate up to 5 days or freeze."]
A19: DB-0018 | B19: Savory Oatmeal with Egg & Avocado | C19: Breakfast | D19: American | E19: 1 | F19: 5 | G19: 12 | H19: 17 | I19: savory-oatmeal-with-egg-and-avocado.jpg | J19: Savory Oatmeal with Egg & Avocado, healthy food photography, plated, natural light | L19: Rolled oats, dry — 40 g (1.4 oz) Chicken broth, low sodium — 200 g (7.1 oz) Egg, large (50 g each) — 50 g (1.8 oz) [1 large egg] Avocado — 50 g (1.8 oz) Green onions (scallions) — 10 g (0.4 oz) Parmesan, grated — 10 g (0.4 oz) Hot sauce (Tabasco/Frank's) — 5 g (0.2 oz) Extra-virgin olive oil — 4 g (0.1 oz) | M19: [{"ingredient_id": "rolled_oats", "name": "Rolled oats, dry", "grams": 40.0, "note": ""}, {"ingredient_id": "chicken_broth", "name": "Chicken broth, low sodium", "grams": 200.0, "note": ""}, {"ingredient_id": "egg", "name": "Egg, large (50 g each)", "grams": 50.0, "note": "1 large egg"}, {"ingredient_id": "avocado", "name": "Avocado", "grams": 50.0, "note": ""}, {"ingredient_id": "green_onion", "name": "Green onions (scallions)", "grams": 10.0, "note": ""}, {"ingredient_id": "parmesan", "name": "Parmesan, grated", "grams": 10.0, "note": ""}, {"ingredient_id": "hot_sauce", "name": "Hot sauce (Tabasco/Frank's)", "grams": 5.0, "note": ""}, {"ingredient_id": "olive_oil", "name": "Extra-virgin olive oil", "grams": 4.0, "note": ""}] | N19: 399 | O19: 18.5 | P19: 22.2 | Q19: 34 | R19: 7.6 | S19: 26.4 | T19: 51 | U19: low | V19: 13.5 | W19: medium | Y19: 88% of this dish's available carbohydrate comes from ingredients with a published, measured GI; the rest uses conventional placeholders (see Ingredients sheet) | Z19: 88 | AA19: vegetarian, nut-free, high-fiber, quick | AB19: 1. Simmer oats in broth for 8–10 minutes, stirring, until creamy. 2. Meanwhile fry the egg in olive oil until the white is set and yolk still runny. 3. Spoon oats into a bowl, top with the egg, sliced avocado, green onion and parmesan. 4. Add a dash of hot sauce. | AC19: ["Simmer oats in broth for 8–10 minutes, stirring, until creamy.", "Meanwhile fry the egg in olive oil until the white is set and yolk still runny.", "Spoon oats into a bowl, top with the egg, sliced avocado, green onion and parmesan.", "Add a dash of hot sauce."]
A20: DB-0019 | B20: Cinnamon Ricotta Bowl with Strawberries | C20: Breakfast | D20: Italian | E20: 1 | F20: 5 | G20: 0 | H20: 5 | I20: cinnamon-ricotta-bowl-with-strawberries.jpg | J20: Cinnamon Ricotta Bowl with Strawberries, healthy food photography, plated, natural light | L20: Ricotta, part-skim — 150 g (5.3 oz) Strawberries — 120 g (4.2 oz) Ground cinnamon — 1 g (0.0 oz) Vanilla extract — 2 g (0.1 oz) Pistachios, shelled — 15 g (0.5 oz) Monk fruit/erythritol sweetener — 3 g (0.1 oz) | M20: [{"ingredient_id": "ricotta", "name": "Ricotta, part-skim", "grams": 150.0, "note": ""}, {"ingredient_id": "strawberries", "name": "Strawberries", "grams": 120.0, "note": ""}, {"ingredient_id": "cinnamon", "name": "Ground cinnamon", "grams": 1.0, "note": ""}, {"ingredient_id": "vanilla_extract", "name": "Vanilla extract", "grams": 2.0, "note": ""}, {"ingredient_id": "pistachios", "name": "Pistachios, shelled", "grams": 15.0, "note": ""}, {"ingredient_id": "monk_fruit_sweetener", "name": "Monk fruit/erythritol sweetener", "grams": 3.0, "note": ""}] | N20: 338 | O20: 20.4 | P20: 19.1 | Q20: 22 | R20: 4.5 | S20: 17.5 | T20: 26 | U20: low | V20: 4.5 | W20: low | Y20: 54% of this dish's available carbohydrate comes from ingredients with a published, measured GI; the rest uses conventional placeholders (see Ingredients sheet) | Z20: 54 | AA20: vegetarian, gluten-free, no-cook, quick | AB20: 1. Whisk ricotta with vanilla, cinnamon and sweetener until fluffy. 2. Spoon into a bowl and top with sliced strawberries. 3. Sprinkle with chopped pistachios. | AC20: ["Whisk ricotta with vanilla, cinnamon and sweetener until fluffy.", "Spoon into a bowl and top with sliced strawberries.", "Sprinkle with chopped pistachios."]
A21: DB-0020 | B21: Huevos Rancheros with Black Beans | C21: Breakfast | D21: Mexican | E21: 2 | F21: 10 | G21: 15 | H21: 25 | I21: huevos-rancheros-with-black-beans.jpg | J21: Huevos Rancheros with Black Beans, healthy food photography, plated, natural light | L21: Corn tortilla — 50 g (1.8 oz) [2 small tortillas] Egg, large (50 g each) — 200 g (7.1 oz) [4 large eggs] Black beans, cooked — 150 g (5.3 oz) Salsa, no sugar added — 120 g (4.2 oz) Avocado — 60 g (2.1 oz) Cotija cheese — 20 g (0.7 oz) Fresh cilantro — 8 g (0.3 oz) Extra-virgin olive oil — 10 g (0.4 oz) Ground cumin — 1 g (0.0 oz) | M21: [{"ingredient_id": "corn_tortilla", "name": "Corn tortilla", "grams": 50.0, "note": "2 small tortillas"}, {"ingredient_id": "egg", "name": "Egg, large (50 g each)", "grams": 200.0, "note": "4 large eggs"}, {"ingredient_id": "black_beans", "name": "Black beans, cooked", "grams": 150.0, "note": ""}, {"ingredient_id": "salsa", "name": "Salsa, no sugar added", "grams": 120.0, "note": ""}, {"ingredient_id": "avocado", "name": "Avocado", "grams": 60.0, "note": ""}, {"ingredient_id": "cotija", "name": "Cotija cheese", "grams": 20.0, "note": ""}, {"ingredient_id": "cilantro", "name": "Fresh cilantro", "grams": 8.0, "note": ""}, {"ingredient_id": "olive_oil", "name": "Extra-virgin olive oil", "grams": 10.0, "note": ""}, {"ingredient_id": "cumin", "name": "Ground cumin", "grams": 1.0, "note": ""}] | N21: 450 | O21: 24.4 | P21: 23.3 | Q21: 37.2 | R21: 11.2 | S21: 26.1 | T21: 36 | U21: low | V21: 9.4 | W21: low | Y21: 80% of this dish's available carbohydrate comes from ingredients with a published, measured GI; the rest uses conventional placeholders (see Ingredients sheet) | Z21: 80 | AA21: vegetarian, gluten-free, nut-free, high-fiber | AB21: 1. Warm black beans with cumin and mash lightly. 2. Toast tortillas in a dry skillet until pliable and lightly charred. 3. Fry the eggs in olive oil until the whites are set. 4. Top each tortilla with beans, two eggs, warm salsa, avocado, cotija and cilantro. | AC21: ["Warm black beans with cumin and mash lightly.", "Toast tortillas in a dry skillet until pliable and lightly charred.", "Fry the eggs in olive oil until the whites are set.", "Top each tortilla with beans, two eggs, warm salsa, avocado, cotija and cilantro."]
A22: DB-0021 | B22: Turkey Bacon, Egg & Cheese English Muffin | C22: Breakfast | D22: American | E22: 1 | F22: 5 | G22: 10 | H22: 15 | I22: turkey-bacon-egg-and-cheese-english-muffin.jpg | J22: Turkey Bacon, Egg & Cheese English Muffin, healthy food photography, plated, natural light | L22: Whole wheat English muffin — 57 g (2.0 oz) [1 muffin] Egg, large (50 g each) — 50 g (1.8 oz) [1 large egg] Turkey bacon — 30 g (1.1 oz) [2 slices] Cheddar cheese — 20 g (0.7 oz) Tomato — 40 g (1.4 oz) Extra-virgin olive oil — 3 g (0.1 oz) | M22: [{"ingredient_id": "whole_wheat_english_muffin", "name": "Whole wheat English muffin", "grams": 57.0, "note": "1 muffin"}, {"ingredient_id": "egg", "name": "Egg, large (50 g each)", "grams": 50.0, "note": "1 large egg"}, {"ingredient_id": "turkey_bacon", "name": "Turkey bacon", "grams": 30.0, "note": "2 slices"}, {"ingredient_id": "cheddar", "name": "Cheddar cheese", "grams": 20.0, "note": ""}, {"ingredient_id": "tomato", "name": "Tomato", "grams": 40.0, "note": ""}, {"ingredient_id": "olive_oil", "name": "Extra-virgin olive oil", "grams": 3.0, "note": ""}] | N22: 377 | O22: 21.8 | P22: 20.1 | Q22: 28.4 | R22: 4.5 | S22: 24 | T22: 41 | U22: low | V22: 9.8 | W22: low | Y22: 90% of this dish's available carbohydrate comes from ingredients with a published, measured GI; the rest uses conventional placeholders (see Ingredients sheet) | Z22: 90 | AA22: nut-free, quick | AB22: 1. Cook turkey bacon in a skillet until crisp; set aside. 2. Fry the egg in olive oil, breaking the yolk for a firmer sandwich. 3. Toast the English muffin and layer cheese, egg, bacon and tomato slices. 4. Close and serve warm. | AC22: ["Cook turkey bacon in a skillet until crisp; set aside.", "Fry the egg in olive oil, breaking the yolk for a firmer sandwich.", "Toast the English muffin and layer cheese, egg, bacon and tomato slices.", "Close and serve warm."]
A23: DB-0022 | B23: Zucchini & Goat Cheese Frittata | C23: Breakfast | D23: Mediterranean | E23: 4 | F23: 10 | G23: 22 | H23: 32 | I23: zucchini-and-goat-cheese-frittata.jpg | J23: Zucchini & Goat Cheese Frittata, healthy food photography, plated, natural light | L23: Egg, large (50 g each) — 350 g (12.3 oz) [7 large eggs] Zucchini — 250 g (8.8 oz) Goat cheese — 60 g (2.1 oz) Yellow onion — 60 g (2.1 oz) Extra-virgin olive oil — 12 g (0.4 oz) Fresh thyme — 2 g (0.1 oz) Salt — 2 g (0.1 oz) Black pepper — 1 g (0.0 oz) | M23: [{"ingredient_id": "egg", "name": "Egg, large (50 g each)", "grams": 350.0, "note": "7 large eggs"}, {"ingredient_id": "zucchini", "name": "Zucchini", "grams": 250.0, "note": ""}, {"ingredient_id": "goat_cheese", "name": "Goat cheese", "grams": 60.0, "note": ""}, {"ingredient_id": "onion", "name": "Yellow onion", "grams": 60.0, "note": ""}, {"ingredient_id": "olive_oil", "name": "Extra-virgin olive oil", "grams": 12.0, "note": ""}, {"ingredient_id": "thyme", "name": "Fresh thyme", "grams": 2.0, "note": ""}, {"ingredient_id": "salt", "name": "Salt", "grams": 2.0, "note": ""}, {"ingredient_id": "black_pepper", "name": "Black pepper", "grams": 1.0, "note": ""}] | N23: 224 | O23: 15.3 | P23: 16 | Q23: 4.2 | R23: 1 | S23: 3.2 | T23: 12 | U23: low | V23: 0.4 | W23: low | X23: Negligible carbohydrate (<5 g net/serving): GI has little practical meaning, glycemic load is what matters. | Y23: 0% of this dish's available carbohydrate comes from ingredients with a published, measured GI; the rest uses conventional placeholders (see Ingredients sheet) | Z23: 0 | AA23: vegetarian, gluten-free, nut-free, low-carb, make-ahead | AB23: 1. Preheat oven to 375°F. Sauté onion and grated zucchini in olive oil in an ovenproof skillet until moisture evaporates, 6 minutes. 2. Whisk eggs with thyme, salt and pepper and pour over the vegetables. 3. Dot with goat cheese and bake 15 minutes until just set. 4. Rest 5 minutes and cut into wedges. | AC23: ["Preheat oven to 375°F. Sauté onion and grated zucchini in olive oil in an ovenproof skillet until moisture evaporates, 6 minutes.", "Whisk eggs with thyme, salt and pepper and pour over the vegetables.", "Dot with goat cheese and bake 15 minutes until just set.", "Rest 5 minutes and cut into wedges."]
A24: DB-0023 | B24: Tofu Veggie Scramble | C24: Breakfast | D24: American | E24: 2 | F24: 10 | G24: 12 | H24: 22 | I24: tofu-veggie-scramble.jpg | J24: Tofu Veggie Scramble, healthy food photography, plated, natural light | L24: Tofu, extra-firm — 300 g (10.6 oz) Bell pepper — 80 g (2.8 oz) Spinach — 60 g (2.1 oz) Yellow onion — 40 g (1.4 oz) Ground turmeric — 2 g (0.1 oz) Nutritional yeast — 10 g (0.4 oz) Extra-virgin olive oil — 10 g (0.4 oz) Garlic powder — 1 g (0.0 oz) Salt — 2 g (0.1 oz) Black pepper — 1 g (0.0 oz) | M24: [{"ingredient_id": "tofu", "name": "Tofu, extra-firm", "grams": 300.0, "note": ""}, {"ingredient_id": "bell_pepper", "name": "Bell pepper", "grams": 80.0, "note": ""}, {"ingredient_id": "spinach", "name": "Spinach", "grams": 60.0, "note": ""}, {"ingredient_id": "onion", "name": "Yellow onion", "grams": 40.0, "note": ""}, {"ingredient_id": "turmeric", "name": "Ground turmeric", "grams": 2.0, "note": ""}, {"ingredient_id": "nutritional_yeast", "name": "Nutritional yeast", "grams": 10.0, "note": ""}, {"ingredient_id": "olive_oil", "name": "Extra-virgin olive oil", "grams": 10.0, "note": ""}, {"ingredient_id": "garlic_powder", "name": "Garlic powder", "grams": 1.0, "note": ""}, {"ingredient_id": "salt", "name": "Salt", "grams": 2.0, "note": ""}, {"ingredient_id": "black_pepper", "name": "Black pepper", "grams": 1.0, "note": ""}] | N24: 310 | O24: 29.7 | P24: 19.1 | Q24: 12.9 | R24: 6.5 | S24: 6.5 | T24: 15 | U24: low | V24: 1 | W24: low | Y24: 0% of this dish's available carbohydrate comes from ingredients with a published, measured GI; the rest uses conventional placeholders (see Ingredients sheet) | Z24: 0 | AA24: vegan, gluten-free, dairy-free, nut-free, low-carb, high-protein, quick | AB24: 1. Press the tofu and crumble it with your hands. 2. Sauté onion and bell pepper in olive oil for 4 minutes, add tofu, turmeric, garlic powder, salt and pepper and cook 5 minutes. 3. Stir in spinach and nutritional yeast and cook until wilted. 4. Serve hot with hot sauce if desired. | AC24: ["Press the tofu and crumble it with your hands.", "Sauté onion and bell pepper in olive oil for 4 minutes, add tofu, turmeric, garlic powder, salt and pepper and cook 5 minutes.", "Stir in spinach and nutritional yeast and cook until wilted.", "Serve hot with hot sauce if desired."]
A25: DB-0024 | B25: Salmon & Asparagus Egg Skillet | C25: Breakfast | D25: American | E25: 2 | F25: 5 | G25: 12 | H25: 17 | I25: salmon-and-asparagus-egg-skillet.jpg | J25: Salmon & Asparagus Egg Skillet, healthy food photography, plated, natural light | L25: Egg, large (50 g each) — 200 g (7.1 oz) [4 large eggs] Canned salmon — 120 g (4.2 oz) Asparagus — 150 g (5.3 oz) Green onions (scallions) — 20 g (0.7 oz) Extra-virgin olive oil — 10 g (0.4 oz) Lemon (with juice & zest) — 20 g (0.7 oz) Fresh dill — 3 g (0.1 oz) Salt — 1 g (0.0 oz) | M25: [{"ingredient_id": "egg", "name": "Egg, large (50 g each)", "grams": 200.0, "note": "4 large eggs"}, {"ingredient_id": "canned_salmon", "name": "Canned salmon", "grams": 120.0, "note": ""}, {"ingredient_id": "asparagus", "name": "Asparagus", "grams": 150.0, "note": ""}, {"ingredient_id": "green_onion", "name": "Green onions (scallions)", "grams": 20.0, "note": ""}, {"ingredient_id": "olive_oil", "name": "Extra-virgin olive oil", "grams": 10.0, "note": ""}, {"ingredient_id": "lemon", "name": "Lemon (with juice & zest)", "grams": 20.0, "note": ""}, {"ingredient_id": "dill", "name": "Fresh dill", "grams": 3.0, "note": ""}, {"ingredient_id": "salt", "name": "Salt", "grams": 1.0, "note": ""}] | N25: 293 | O25: 26.6 | P25: 18.2 | Q25: 5.4 | R25: 2.1 | S25: 3.2 | T25: 13 | U25: low | V25: 0.4 | W25: low | X25: Negligible carbohydrate (<5 g net/serving): GI has little practical meaning, glycemic load is what matters. | Y25: 0% of this dish's available carbohydrate comes from ingredients with a published, measured GI; the rest uses conventional placeholders (see Ingredients sheet) | Z25: 0 | AA25: pescatarian, gluten-free, dairy-free, nut-free, low-carb, high-protein, quick, omega-3 | AB25: 1. Sauté chopped asparagus in olive oil for 4 minutes until crisp-tender. 2. Add flaked salmon and green onion and warm through. 3. Pour in whisked eggs seasoned with salt and stir gently until softly scrambled. 4. Finish with dill and a squeeze of lemon. | AC25: ["Sauté chopped asparagus in olive oil for 4 minutes until crisp-tender.", "Add flaked salmon and green onion and warm through.", "Pour in whisked eggs seasoned with salt and stir gently until softly scrambled.", "Finish with dill and a squeeze of lemon."]
A26: DB-0025 | B26: Peanut Butter Chia Overnight Oats | C26: Breakfast | D26: American | E26: 1 | F26: 5 | G26: 0 | H26: 5 | I26: peanut-butter-chia-overnight-oats.jpg | J26: Peanut Butter Chia Overnight Oats, healthy food photography, plated, natural light | L26: Rolled oats, dry — 40 g (1.4 oz) Chia seeds — 10 g (0.4 oz) Almond milk, unsweetened — 180 g (6.3 oz) Peanut butter, natural — 16 g (0.6 oz) Greek yogurt, plain 2% — 60 g (2.1 oz) Strawberries — 60 g (2.1 oz) Ground cinnamon — 1 g (0.0 oz) | M26: [{"ingredient_id": "rolled_oats", "name": "Rolled oats, dry", "grams": 40.0, "note": ""}, {"ingredient_id": "chia_seeds", "name": "Chia seeds", "grams": 10.0, "note": ""}, {"ingredient_id": "almond_milk", "name": "Almond milk, unsweetened", "grams": 180.0, "note": ""}, {"ingredient_id": "peanut_butter", "name": "Peanut butter, natural", "grams": 16.0, "note": ""}, {"ingredient_id": "greek_yogurt", "name": "Greek yogurt, plain 2%", "grams": 60.0, "note": ""}, {"ingredient_id": "strawberries", "name": "Strawberries", "grams": 60.0, "note": ""}, {"ingredient_id": "cinnamon", "name": "Ground cinnamon", "grams": 1.0, "note": ""}] | N26: 387 | O26: 18.4 | P26: 17.3 | Q26: 43.5 | R26: 10.1 | S26: 33.4 | T26: 47 | U26: low | V26: 15.7 | W26: medium | Y26: 87% of this dish's available carbohydrate comes from ingredients with a published, measured GI; the rest uses conventional placeholders (see Ingredients sheet) | Z26: 87 | AA26: vegetarian, high-fiber, no-cook, make-ahead | AB26: 1. Stir oats, chia, almond milk, yogurt, peanut butter and cinnamon together in a jar. 2. Refrigerate overnight. 3. Top with sliced strawberries before eating. | AC26: ["Stir oats, chia, almond milk, yogurt, peanut butter and cinnamon together in a jar.", "Refrigerate overnight.", "Top with sliced strawberries before eating."]
A27: DB-0026 | B27: Breakfast Tacos with Eggs & Pico | C27: Breakfast | D27: Tex-Mex | E27: 2 | F27: 10 | G27: 8 | H27: 18 | I27: breakfast-tacos-with-eggs-and-pico.jpg | J27: Breakfast Tacos with Eggs & Pico, healthy food photography, plated, natural light | L27: Corn tortilla — 75 g (2.6 oz) [3 small tortillas] Egg, large (50 g each) — 150 g (5.3 oz) [3 large eggs] Pico de gallo — 90 g (3.2 oz) Avocado — 60 g (2.1 oz) Cheddar cheese — 30 g (1.1 oz) Fresh cilantro — 5 g (0.2 oz) Extra-virgin olive oil — 6 g (0.2 oz) Jalapeño — 10 g (0.4 oz) | M27: [{"ingredient_id": "corn_tortilla", "name": "Corn tortilla", "grams": 75.0, "note": "3 small tortillas"}, {"ingredient_id": "egg", "name": "Egg, large (50 g each)", "grams": 150.0, "note": "3 large eggs"}, {"ingredient_id": "pico_de_gallo", "name": "Pico de gallo", "grams": 90.0, "note": ""}, {"ingredient_id": "avocado", "name": "Avocado", "grams": 60.0, "note": ""}, {"ingredient_id": "cheddar", "name": "Cheddar cheese", "grams": 30.0, "note": ""}, {"ingredient_id": "cilantro", "name": "Fresh cilantro", "grams": 5.0, "note": ""}, {"ingredient_id": "olive_oil", "name": "Extra-virgin olive oil", "grams": 6.0, "note": ""}, {"ingredient_id": "jalapeno", "name": "Jalapeño", "grams": 10.0, "note": ""}] | N27: 335 | O27: 16.1 | P27: 20.8 | Q27: 22.6 | R27: 5.1 | S27: 17.5 | T27: 45 | U27: low | V27: 7.9 | W27: low | Y27: 83% of this dish's available carbohydrate comes from ingredients with a published, measured GI; the rest uses conventional placeholders (see Ingredients sheet) | Z27: 83 | AA27: vegetarian, gluten-free, nut-free, quick | AB27: 1. Whisk the eggs and scramble softly in olive oil. 2. Warm tortillas in a dry skillet. 3. Fill each with eggs, cheddar, pico de gallo, avocado and sliced jalapeño. 4. Top with cilantro and serve. | AC27: ["Whisk the eggs and scramble softly in olive oil.", "Warm tortillas in a dry skillet.", "Fill each with eggs, cheddar, pico de gallo, avocado and sliced jalapeño.", "Top with cilantro and serve."]
A28: DB-0027 | B28: Cauliflower Hash Browns with Fried Eggs | C28: Breakfast | D28: American | E28: 2 | F28: 15 | G28: 15 | H28: 30 | I28: cauliflower-hash-browns-with-fried-eggs.jpg | J28: Cauliflower Hash Browns with Fried Eggs, healthy food photography, plated, natural light | L28: Cauliflower rice — 300 g (10.6 oz) Egg, large (50 g each) — 200 g (7.1 oz) [4 large eggs (2 in hash)] Parmesan, grated — 30 g (1.1 oz) Green onions (scallions) — 20 g (0.7 oz) Garlic powder — 1 g (0.0 oz) Extra-virgin olive oil — 15 g (0.5 oz) Salt — 2 g (0.1 oz) | M28: [{"ingredient_id": "cauliflower_rice", "name": "Cauliflower rice", "grams": 300.0, "note": ""}, {"ingredient_id": "egg", "name": "Egg, large (50 g each)", "grams": 200.0, "note": "4 large eggs (2 in hash)"}, {"ingredient_id": "parmesan", "name": "Parmesan, grated", "grams": 30.0, "note": ""}, {"ingredient_id": "green_onion", "name": "Green onions (scallions)", "grams": 20.0, "note": ""}, {"ingredient_id": "garlic_powder", "name": "Garlic powder", "grams": 1.0, "note": ""}, {"ingredient_id": "olive_oil", "name": "Extra-virgin olive oil", "grams": 15.0, "note": ""}, {"ingredient_id": "salt", "name": "Salt", "grams": 2.0, "note": ""}] | N28: 316 | O28: 21.4 | P28: 21.8 | Q28: 9.9 | R28: 3.3 | S28: 6.6 | T28: 12 | U28: low | V28: 0.8 | W28: low | Y28: 0% of this dish's available carbohydrate comes from ingredients with a published, measured GI; the rest uses conventional placeholders (see Ingredients sheet) | Z28: 0 | AA28: vegetarian, gluten-free, nut-free, low-carb | AB28: 1. Microwave cauliflower rice 4 minutes, cool and squeeze dry in a clean towel. 2. Mix with 2 beaten eggs, parmesan, green onion, garlic powder and salt; form 4 patties. 3. Pan-fry in olive oil 4–5 minutes per side until golden and crisp. 4. Fry the remaining 2 eggs and serve on top of the hash browns. | AC28: ["Microwave cauliflower rice 4 minutes, cool and squeeze dry in a clean towel.", "Mix with 2 beaten eggs, parmesan, green onion, garlic powder and salt; form 4 patties.", "Pan-fry in olive oil 4–5 minutes per side until golden and crisp.", "Fry the remaining 2 eggs and serve on top of the hash browns."]
A29: DB-0028 | B29: Denver Omelet | C29: Breakfast | D29: American | E29: 1 | F29: 5 | G29: 10 | H29: 15 | I29: denver-omelet.jpg | J29: Denver Omelet, healthy food photography, plated, natural light | L29: Egg, large (50 g each) — 150 g (5.3 oz) [3 large eggs] Ham, lean — 50 g (1.8 oz) Bell pepper — 50 g (1.8 oz) Yellow onion — 30 g (1.1 oz) Cheddar cheese — 25 g (0.9 oz) Extra-virgin olive oil — 6 g (0.2 oz) Salt — 1 g (0.0 oz) Black pepper — 1 g (0.0 oz) | M29: [{"ingredient_id": "egg", "name": "Egg, large (50 g each)", "grams": 150.0, "note": "3 large eggs"}, {"ingredient_id": "ham", "name": "Ham, lean", "grams": 50.0, "note": ""}, {"ingredient_id": "bell_pepper", "name": "Bell pepper", "grams": 50.0, "note": ""}, {"ingredient_id": "onion", "name": "Yellow onion", "grams": 30.0, "note": ""}, {"ingredient_id": "cheddar", "name": "Cheddar cheese", "grams": 25.0, "note": ""}, {"ingredient_id": "olive_oil", "name": "Extra-virgin olive oil", "grams": 6.0, "note": ""}, {"ingredient_id": "salt", "name": "Salt", "grams": 1.0, "note": ""}, {"ingredient_id": "black_pepper", "name": "Black pepper", "grams": 1.0, "note": ""}] | N29: 471 | O29: 36.1 | P29: 31.7 | Q29: 8.6 | R29: 1.8 | S29: 6.7 | T29: 10 | U29: low | V29: 0.7 | W29: low | Y29: 0% of this dish's available carbohydrate comes from ingredients with a published, measured GI; the rest uses conventional placeholders (see Ingredients sheet) | Z29: 0 | AA29: gluten-free, nut-free, low-carb, high-protein, quick | AB29: 1. Sauté diced ham, bell pepper and onion in olive oil for 4 minutes. 2. Pour in whisked, seasoned eggs and cook until nearly set. 3. Sprinkle cheddar over one half, fold and cook 1 minute more. 4. Slide onto a plate. | AC29: ["Sauté diced ham, bell pepper and onion in olive oil for 4 minutes.", "Pour in whisked, seasoned eggs and cook until nearly set.", "Sprinkle cheddar over one half, fold and cook 1 minute more.", "Slide onto a plate."]
