Workbook

Sheet README
B2: DiaBite — Financial Model
B3: Three-year operating model · seed round · 20 October 2026
B5: How to use this workbook
B6: Edit only the blue cells | C6: All blue figures on the Assumptions and Team tabs are inputs. Everything in black is a formula and will update.
B7: Three live scenarios | C7: Conservative, Base and Upside each have their own monthly tab, each reading its own column of Assumptions. All three recalculate; none is hardcoded.
B8: Yellow fill | C8: The assumptions that move the outcome most. Change these first.
B9: Currency | C9: US dollars. Costs are incurred in euros and converted at the rate on the Assumptions tab.
B11: Tabs
B12: Assumptions | C12: Every driver, with its provenance. Three scenario columns.
B13: Team | C13: The hiring plan. Loaded monthly cost per role, with start months and raises.
B14: Base / Conservative / Upside | C14: The monthly model, 36 months. Identical structure, different assumption column.
B15: Summary | C15: Annual P&L for all three scenarios, funding, cash, and the charts.
B16: Unit Economics | C16: Per-subscriber economics, LTV, CAC and payback, by scenario.
B18: Provenance — read this before trusting a number
B19: MEASURED | C19: From Azure Cost Management and production traces over 1,941 live agent questions, 27 September to 8 October 2026. The cost of goods is measured, not forecast.
B20: SCOPED | C20: A size in working days from docs/PRD-post-course.md.
B21: ASSUMED | C21: No measurement behind it. THERE ARE NO USERS YET, so every growth figure is assumed. The two that matter most — free-to-paid conversion and monthly churn — are marked in yellow.
B22: TO VERIFY | C22: Market figures recalled from CDC and ADA publications, not yet re-checked against the primary source.
B24: What this model deliberately excludes
C25: Photo and voice logging · branded-food licensing · app-store fees (the product is web-first at 2.9%) · corporate taxes · any revenue from payer, employer or clinician-facing channels. Each is a credible expansion; none is underwritten here.
C27: Source documents: docs/FINANCIAL_PLAN.md (the narrative), docs/COST-post-course.md and docs/monitoring.md (the measured costs), docs/PRD-post-course.md (the scope).
B29: Legend
B30: Blue | C30: hardcoded input — edit these
B31: Black | C31: formula — do not overwrite
B32: Green | C32: link to another tab
B33: Yellow fill | C33: the assumptions that decide the outcome

Sheet Summary
B2: DiaBite — Summary
B3: All three scenarios are live. Every figure below is a formula over the monthly tabs; change an assumption and this page follows.
C5: Conservative | F5: Base | I5: Upside
B6: Three-year P&L | C6: Year 1 | D6: Year 2 | E6: Year 3 | F6: Year 1 | G6: Year 2 | H6: Year 3 | I6: Year 1 | J6: Year 2 | K6: Year 3
B7: Paying subscribers, exit | C7: ='Conservative'!N22 | D7: ='Conservative'!Z22 | E7: ='Conservative'!AL22 | F7: ='Base'!N22 | G7: ='Base'!Z22 | H7: ='Base'!AL22 | I7: ='Upside'!N22 | J7: ='Upside'!Z22 | K7: ='Upside'!AL22
B8: Free users, exit | C8: ='Conservative'!N19 | D8: ='Conservative'!Z19 | E8: ='Conservative'!AL19 | F8: ='Base'!N19 | G8: ='Base'!Z19 | H8: ='Base'!AL19 | I8: ='Upside'!N19 | J8: ='Upside'!Z19 | K8: ='Upside'!AL19
B9: Exit ARR | C9: ='Conservative'!N23 | D9: ='Conservative'!Z23 | E9: ='Conservative'!AL23 | F9: ='Base'!N23 | G9: ='Base'!Z23 | H9: ='Base'!AL23 | I9: ='Upside'!N23 | J9: ='Upside'!Z23 | K9: ='Upside'!AL23
B10: Revenue | C10: =SUM('Conservative'!C26:N26) | D10: =SUM('Conservative'!O26:Z26) | E10: =SUM('Conservative'!AA26:AL26) | F10: =SUM('Base'!C26:N26) | G10: =SUM('Base'!O26:Z26) | H10: =SUM('Base'!AA26:AL26) | I10: =SUM('Upside'!C26:N26) | J10: =SUM('Upside'!O26:Z26) | K10: =SUM('Upside'!AA26:AL26)
B11: Cost of goods | C11: =SUM('Conservative'!C32:N32) | D11: =SUM('Conservative'!O32:Z32) | E11: =SUM('Conservative'!AA32:AL32) | F11: =SUM('Base'!C32:N32) | G11: =SUM('Base'!O32:Z32) | H11: =SUM('Base'!AA32:AL32) | I11: =SUM('Upside'!C32:N32) | J11: =SUM('Upside'!O32:Z32) | K11: =SUM('Upside'!AA32:AL32)
B12: Gross profit | C12: =SUM('Conservative'!C33:N33) | D12: =SUM('Conservative'!O33:Z33) | E12: =SUM('Conservative'!AA33:AL33) | F12: =SUM('Base'!C33:N33) | G12: =SUM('Base'!O33:Z33) | H12: =SUM('Base'!AA33:AL33) | I12: =SUM('Upside'!C33:N33) | J12: =SUM('Upside'!O33:Z33) | K12: =SUM('Upside'!AA33:AL33)
B13: Gross margin | C13: =IFERROR(SUM('Conservative'!C33:N33)/SUM('Conservative'!C26:N26),0) | D13: =IFERROR(SUM('Conservative'!O33:Z33)/SUM('Conservative'!O26:Z26),0) | E13: =IFERROR(SUM('Conservative'!AA33:AL33)/SUM('Conservative'!AA26:AL26),0) | F13: =IFERROR(SUM('Base'!C33:N33)/SUM('Base'!C26:N26),0) | G13: =IFERROR(SUM('Base'!O33:Z33)/SUM('Base'!O26:Z26),0) | H13: =IFERROR(SUM('Base'!AA33:AL33)/SUM('Base'!AA26:AL26),0) | I13: =IFERROR(SUM('Upside'!C33:N33)/SUM('Upside'!C26:N26),0) | J13: =IFERROR(SUM('Upside'!O33:Z33)/SUM('Upside'!O26:Z26),0) | K13: =IFERROR(SUM('Upside'!AA33:AL33)/SUM('Upside'!AA26:AL26),0)
B14: Personnel | C14: =SUM('Conservative'!C37:N37) | D14: =SUM('Conservative'!O37:Z37) | E14: =SUM('Conservative'!AA37:AL37) | F14: =SUM('Base'!C37:N37) | G14: =SUM('Base'!O37:Z37) | H14: =SUM('Base'!AA37:AL37) | I14: =SUM('Upside'!C37:N37) | J14: =SUM('Upside'!O37:Z37) | K14: =SUM('Upside'!AA37:AL37)
B15: Sales and marketing | C15: =SUM('Conservative'!C38:N38) | D15: =SUM('Conservative'!O38:Z38) | E15: =SUM('Conservative'!AA38:AL38) | F15: =SUM('Base'!C38:N38) | G15: =SUM('Base'!O38:Z38) | H15: =SUM('Base'!AA38:AL38) | I15: =SUM('Upside'!C38:N38) | J15: =SUM('Upside'!O38:Z38) | K15: =SUM('Upside'!AA38:AL38)
B16: G&A, legal, compliance, data | C16: =SUM('Conservative'!C39:N39)+SUM('Conservative'!C40:N40) | D16: =SUM('Conservative'!O39:Z39)+SUM('Conservative'!O40:Z40) | E16: =SUM('Conservative'!AA39:AL39)+SUM('Conservative'!AA40:AL40) | F16: =SUM('Base'!C39:N39)+SUM('Base'!C40:N40) | G16: =SUM('Base'!O39:Z39)+SUM('Base'!O40:Z40) | H16: =SUM('Base'!AA39:AL39)+SUM('Base'!AA40:AL40) | I16: =SUM('Upside'!C39:N39)+SUM('Upside'!C40:N40) | J16: =SUM('Upside'!O39:Z39)+SUM('Upside'!O40:Z40) | K16: =SUM('Upside'!AA39:AL39)+SUM('Upside'!AA40:AL40)
B17: Fixed infrastructure | C17: =SUM('Conservative'!C41:N41) | D17: =SUM('Conservative'!O41:Z41) | E17: =SUM('Conservative'!AA41:AL41) | F17: =SUM('Base'!C41:N41) | G17: =SUM('Base'!O41:Z41) | H17: =SUM('Base'!AA41:AL41) | I17: =SUM('Upside'!C41:N41) | J17: =SUM('Upside'!O41:Z41) | K17: =SUM('Upside'!AA41:AL41)
B18: Total operating expense | C18: =SUM('Conservative'!C42:N42) | D18: =SUM('Conservative'!O42:Z42) | E18: =SUM('Conservative'!AA42:AL42) | F18: =SUM('Base'!C42:N42) | G18: =SUM('Base'!O42:Z42) | H18: =SUM('Base'!AA42:AL42) | I18: =SUM('Upside'!C42:N42) | J18: =SUM('Upside'!O42:Z42) | K18: =SUM('Upside'!AA42:AL42)
B19: EBITDA | C19: =SUM('Conservative'!C45:N45) | D19: =SUM('Conservative'!O45:Z45) | E19: =SUM('Conservative'!AA45:AL45) | F19: =SUM('Base'!C45:N45) | G19: =SUM('Base'!O45:Z45) | H19: =SUM('Base'!AA45:AL45) | I19: =SUM('Upside'!C45:N45) | J19: =SUM('Upside'!O45:Z45) | K19: =SUM('Upside'!AA45:AL45)
B20: Headcount, exit | C20: ='Conservative'!N49 | D20: ='Conservative'!Z49 | E20: ='Conservative'!AL49 | F20: ='Base'!N49 | G20: ='Base'!Z49 | H20: ='Base'!AL49 | I20: ='Upside'!N49 | J20: ='Upside'!Z49 | K20: ='Upside'!AL49
B22: Funding and cash
B23: Seed raised | C23: =Assumptions!$C$63 | F23: =Assumptions!$D$63 | I23: =Assumptions!$E$63
B24: Series A raised | C24: =Assumptions!$C$65 | F24: =Assumptions!$D$65 | I24: =Assumptions!$E$65
B25: Peak cumulative cash requirement | C25: =-MIN('Conservative'!C46:AL46) | F25: =-MIN('Base'!C46:AL46) | I25: =-MIN('Upside'!C46:AL46)
B26: Cash at the Series A, before it closes | C26: =INDEX('Conservative'!C48:AL48,Assumptions!$C$66-1) | F26: =INDEX('Base'!C48:AL48,Assumptions!$D$66-1) | I26: =INDEX('Upside'!C48:AL48,Assumptions!$E$66-1)
B27: First EBITDA-positive month | C27: =IF(MIN('Conservative'!C51:AL51)=999,"beyond 36",MIN('Conservative'!C51:AL51)) | F27: =IF(MIN('Base'!C51:AL51)=999,"beyond 36",MIN('Base'!C51:AL51)) | I27: =IF(MIN('Upside'!C51:AL51)=999,"beyond 36",MIN('Upside'!C51:AL51))
B28: Cash on hand, month 36 | C28: ='Conservative'!AL48 | F28: ='Base'!AL48 | I28: ='Upside'!AL48
B31: Exit ARR by quarter
B32: Quarter | C32: Conservative | D32: Base | E32: Upside
B33: Q1 | C33: ='Conservative'!E23 | D33: ='Base'!E23 | E33: ='Upside'!E23
B34: Q2 | C34: ='Conservative'!H23 | D34: ='Base'!H23 | E34: ='Upside'!H23
B35: Q3 | C35: ='Conservative'!K23 | D35: ='Base'!K23 | E35: ='Upside'!K23
B36: Q4 | C36: ='Conservative'!N23 | D36: ='Base'!N23 | E36: ='Upside'!N23
B37: Q5 | C37: ='Conservative'!Q23 | D37: ='Base'!Q23 | E37: ='Upside'!Q23
B38: Q6 | C38: ='Conservative'!T23 | D38: ='Base'!T23 | E38: ='Upside'!T23
B39: Q7 | C39: ='Conservative'!W23 | D39: ='Base'!W23 | E39: ='Upside'!W23
B40: Q8 | C40: ='Conservative'!Z23 | D40: ='Base'!Z23 | E40: ='Upside'!Z23
B41: Q9 | C41: ='Conservative'!AC23 | D41: ='Base'!AC23 | E41: ='Upside'!AC23
B42: Q10 | C42: ='Conservative'!AF23 | D42: ='Base'!AF23 | E42: ='Upside'!AF23
B43: Q11 | C43: ='Conservative'!AI23 | D43: ='Base'!AI23 | E43: ='Upside'!AI23
B44: Q12 | C44: ='Conservative'!AL23 | D44: ='Base'!AL23 | E44: ='Upside'!AL23
B46: Cash on hand, base case
...

Sheet Assumptions
B2: DiaBite — Assumptions
B3: Blue cells are inputs. Yellow fill marks the assumptions that decide the outcome.
C5: Conservative | D5: Base | E5: Upside | F5: Unit | G5: Provenance and note
B7: Foreign exchange
B8: EUR to USD | C8: 1.093 | D8: 1.093 | E8: 1.093 | F8: $ per € | G8: ASSUMED · Azure bills in euros; the team is EU-based
B10: Pricing
B11: Monthly plan price | C11: 19.99 | D11: 19.99 | E11: 19.99 | F11: $ / month | G11: ASSUMED · not tested on a user; set from the sessions and the beta
B12: Annual plan price | C12: 149 | D12: 149 | E12: 149 | F12: $ / year | G12: ASSUMED · 7.45x the monthly price
B13: Monthly plan share of new subscriptions | C13: 0.55 | D13: 0.55 | E13: 0.55 | F13: % of new | G13: ASSUMED · the annual plan carries ~2x the lifetime
B15: Cost of goods — MEASURED unless stated
B16: Inference cost per agent question | C16: 0.0028 | D16: 0.0028 | E16: 0.0028 | F16: $ / question | G16: MEASURED · 1,941 production questions, 27 Sep–8 Oct 2026, incl. retries, verifier second attempts and eval runs
B17: Questions per paying subscriber | C17: 135 | D17: 135 | E17: 135 | F17: / month | G17: ASSUMED · 4.5 a day, from the PRD; instrument from launch
B18: Questions per free user (ceiling) | C18: 15 | D18: 15 | E18: 15 | F18: / month | G18: DECIDED · the free tier's hard cost ceiling
B19: Hosting per paying subscriber | C19: 0.12 | D19: 0.12 | E19: 0.12 | F19: $ / month | G19: ASSUMED · scales off the measured $28/mo fixed base
B20: Support per paying subscriber | C20: 0.25 | D20: 0.25 | E20: 0.25 | F20: $ / month | G20: ASSUMED
B21: Card fee, percentage | C21: 0.029 | D21: 0.029 | E21: 0.029 | F21: % of charge | G21: ASSUMED · a Poland-based account charging US cards may pay more
B22: Card fee, fixed per charge | C22: 0.3 | D22: 0.3 | E22: 0.3 | F22: $ / charge | G22: ASSUMED
B24: Launch and acquisition
B25: Launch month | C25: 6 | D25: 6 | E25: 6 | F25: month # | G25: SCOPED · 83–106 working days to a public launch, against the hiring plan
B26: Organic signups in the launch month | C26: 300 | D26: 500 | E26: 750 | F26: / month | G26: ASSUMED · clinicians, dietitians, condition communities, search
B27: Organic growth | C27: 0.09 | D27: 0.09 | E27: 0.09 | F27: / month | G27: ASSUMED · content compounds
B28: Free-user churn | C28: 0.11 | D28: 0.11 | E28: 0.11 | F28: / month | G28: ASSUMED
B29: Upgrade from the existing free base | C29: 0.004 | D29: 0.006 | E29: 0.009 | F29: / month | G29: ASSUMED - free users who convert later, not at signup. Compounds as the free base grows
B31: Cost per registered signup, paid channels
B32: Year 1 | C32: 9.1 | D32: 7 | E32: 5.95 | F32: $ / signup | G32: ASSUMED · no channel test has been run
B33: Year 2 | C33: 7.8 | D33: 6 | E33: 5.1 | F33: $ / signup | G33: ASSUMED · improves as creative and targeting mature
B34: Year 3 | C34: 9.75 | D34: 7.5 | E34: 6.38 | F34: $ / signup | G34: ASSUMED · rises as paid channels saturate — modelled, not an oversight
B36: Free to paid conversion
B37: Year 1 | C37: 0.042 | D37: 0.06 | E37: 0.075 | F37: % of signups | G37: ASSUMED · worth 43% of Year 3 ARR. The first two cohorts replace it
B38: Year 2 | C38: 0.049 | D38: 0.07 | E38: 0.088 | G38: ASSUMED
B39: Year 3 | C39: 0.053 | D39: 0.075 | E39: 0.094 | G39: ASSUMED
B41: Monthly-plan churn
B42: Year 1 | C42: 0.1 | D42: 0.08 | E42: 0.066 | F42: / month | G42: ASSUMED · consumer health churns hard; the month-3 cohort curve replaces it
B43: Year 2 | C43: 0.085 | D43: 0.068 | E43: 0.056 | G43: ASSUMED
B44: Year 3 | C44: 0.073 | D44: 0.058 | E44: 0.048 | G44: ASSUMED
B46: Annual-plan renewal
B47: Year 1 | C47: 0.5 | D47: 0.55 | E47: 0.6 | F47: / year | G47: ASSUMED
B48: Year 2 | C48: 0.54 | D48: 0.6 | E48: 0.66 | G48: ASSUMED
B49: Year 3 | C49: 0.58 | D49: 0.65 | E49: 0.71 | G49: ASSUMED
B51: Fixed infrastructure
...

Sheet Team
B2: DiaBite — hiring plan
B3: Fully loaded monthly cost: salary, employer contributions, equipment, tooling. The team is EU-based at roughly 60% of US loaded cost, except the US medical director, who is deliberately paid at a US rate. ASSUMED — no offers have been made.
B4: 999 in an end or raise column means it never happens. Blue cells are inputs.
B6: Role | C6: Start | D6: End | E6: Cost | F6: Raise 1 | G6: Cost 2 | H6: Raise 2 | I6: Cost 3 | J6: 1 | K6: 2 | L6: 3 | M6: 4 | N6: 5 | O6: 6 | P6: 7 | Q6: 8 | R6: 9 | S6: 10 | T6: 11 | U6: 12 | V6: 13 | W6: 14 | X6: 15 | Y6: 16 | Z6: 17 | AA6: 18 | AB6: 19 | AC6: 20 | AD6: 21 | AE6: 22 | AF6: 23 | AG6: 24 | AH6: 25 | AI6: 26 | AJ6: 27 | AK6: 28 | AL6: 29 | AM6: 30 | AN6: 31 | AO6: 32 | AP6: 33 | AQ6: 34 | AR6: 35 | AS6: 36
B7: Founder / CEO | C7: 1 | D7: 999 | E7: 7500 | F7: 13 | G7: 9500 | H7: 25 | I7: 11500 | J7: =IF(OR(1<$C7,1>$D7),0,IF(1>=$H7,$I7,IF(1>=$F7,$G7,$E7))) | K7: =IF(OR(2<$C7,2>$D7),0,IF(2>=$H7,$I7,IF(2>=$F7,$G7,$E7))) | L7: =IF(OR(3<$C7,3>$D7),0,IF(3>=$H7,$I7,IF(3>=$F7,$G7,$E7))) | M7: =IF(OR(4<$C7,4>$D7),0,IF(4>=$H7,$I7,IF(4>=$F7,$G7,$E7))) | N7: =IF(OR(5<$C7,5>$D7),0,IF(5>=$H7,$I7,IF(5>=$F7,$G7,$E7))) | O7: =IF(OR(6<$C7,6>$D7),0,IF(6>=$H7,$I7,IF(6>=$F7,$G7,$E7))) | P7: =IF(OR(7<$C7,7>$D7),0,IF(7>=$H7,$I7,IF(7>=$F7,$G7,$E7))) | Q7: =IF(OR(8<$C7,8>$D7),0,IF(8>=$H7,$I7,IF(8>=$F7,$G7,$E7))) | R7: =IF(OR(9<$C7,9>$D7),0,IF(9>=$H7,$I7,IF(9>=$F7,$G7,$E7))) | S7: =IF(OR(10<$C7,10>$D7),0,IF(10>=$H7,$I7,IF(10>=$F7,$G7,$E7))) | T7: =IF(OR(11<$C7,11>$D7),0,IF(11>=$H7,$I7,IF(11>=$F7,$G7,$E7))) | U7: =IF(OR(12<$C7,12>$D7),0,IF(12>=$H7,$I7,IF(12>=$F7,$G7,$E7))) | V7: =IF(OR(13<$C7,13>$D7),0,IF(13>=$H7,$I7,IF(13>=$F7,$G7,$E7))) | W7: =IF(OR(14<$C7,14>$D7),0,IF(14>=$H7,$I7,IF(14>=$F7,$G7,$E7))) | X7: =IF(OR(15<$C7,15>$D7),0,IF(15>=$H7,$I7,IF(15>=$F7,$G7,$E7))) | Y7: =IF(OR(16<$C7,16>$D7),0,IF(16>=$H7,$I7,IF(16>=$F7,$G7,$E7))) | Z7: =IF(OR(17<$C7,17>$D7),0,IF(17>=$H7,$I7,IF(17>=$F7,$G7,$E7))) | AA7: =IF(OR(18<$C7,18>$D7),0,IF(18>=$H7,$I7,IF(18>=$F7,$G7,$E7))) | AB7: =IF(OR(19<$C7,19>$D7),0,IF(19>=$H7,$I7,IF(19>=$F7,$G7,$E7))) | AC7: =IF(OR(20<$C7,20>$D7),0,IF(20>=$H7,$I7,IF(20>=$F7,$G7,$E7))) | AD7: =IF(OR(21<$C7,21>$D7),0,IF(21>=$H7,$I7,IF(21>=$F7,$G7,$E7))) | AE7: =IF(OR(22<$C7,22>$D7),0,IF(22>=$H7,$I7,IF(22>=$F7,$G7,$E7))) | AF7: =IF(OR(23<$C7,23>$D7),0,IF(23>=$H7,$I7,IF(23>=$F7,$G7,$E7))) | AG7: =IF(OR(24<$C7,24>$D7),0,IF(24>=$H7,$I7,IF(24>=$F7,$G7,$E7))) | AH7: =IF(OR(25<$C7,25>$D7),0,IF(25>=$H7,$I7,IF(25>=$F7,$G7,$E7))) | AI7: =IF(OR(26<$C7,26>$D7),0,IF(26>=$H7,$I7,IF(26>=$F7,$G7,$E7))) | AJ7: =IF(OR(27<$C7,27>$D7),0,IF(27>=$H7,$I7,IF(27>=$F7,$G7,$E7))) | AK7: =IF(OR(28<$C7,28>$D7),0,IF(28>=$H7,$I7,IF(28>=$F7,$G7,$E7))) | AL7: =IF(OR(29<$C7,29>$D7),0,IF(29>=$H7,$I7,IF(29>=$F7,$G7,$E7))) | AM7: =IF(OR(30<$C7,30>$D7),0,IF(30>=$H7,$I7,IF(30>=$F7,$G7,$E7))) | AN7: =IF(OR(31<$C7,31>$D7),0,IF(31>=$H7,$I7,IF(31>=$F7,$G7,$E7))) | AO7: =IF(OR(32<$C7,32>$D7),0,IF(32>=$H7,$I7,IF(32>=$F7,$G7,$E7))) | AP7: =IF(OR(33<$C7,33>$D7),0,IF(33>=$H7,$I7,IF(33>=$F7,$G7,$E7))) | AQ7: =IF(OR(34<$C7,34>$D7),0,IF(34>=$H7,$I7,IF(34>=$F7,$G7,$E7))) | AR7: =IF(OR(35<$C7,35>$D7),0,IF(35>=$H7,$I7,IF(35>=$F7,$G7,$E7))) | AS7: =IF(OR(36<$C7,36>$D7),0,IF(36>=$H7,$I7,IF(36>=$F7,$G7,$E7)))
B8: AI / agent engineer | C8: 1 | D8: 999 | E8: 10000 | F8: 999 | G8: 10000 | H8: 999 | I8: 10000 | J8: =IF(OR(1<$C8,1>$D8),0,IF(1>=$H8,$I8,IF(1>=$F8,$G8,$E8))) | K8: =IF(OR(2<$C8,2>$D8),0,IF(2>=$H8,$I8,IF(2>=$F8,$G8,$E8))) | L8: =IF(OR(3<$C8,3>$D8),0,IF(3>=$H8,$I8,IF(3>=$F8,$G8,$E8))) | M8: =IF(OR(4<$C8,4>$D8),0,IF(4>=$H8,$I8,IF(4>=$F8,$G8,$E8))) | N8: =IF(OR(5<$C8,5>$D8),0,IF(5>=$H8,$I8,IF(5>=$F8,$G8,$E8))) | O8: =IF(OR(6<$C8,6>$D8),0,IF(6>=$H8,$I8,IF(6>=$F8,$G8,$E8))) | P8: =IF(OR(7<$C8,7>$D8),0,IF(7>=$H8,$I8,IF(7>=$F8,$G8,$E8))) | Q8: =IF(OR(8<$C8,8>$D8),0,IF(8>=$H8,$I8,IF(8>=$F8,$G8,$E8))) | R8: =IF(OR(9<$C8,9>$D8),0,IF(9>=$H8,$I8,IF(9>=$F8,$G8,$E8))) | S8: =IF(OR(10<$C8,10>$D8),0,IF(10>=$H8,$I8,IF(10>=$F8,$G8,$E8))) | T8: =IF(OR(11<$C8,11>$D8),0,IF(11>=$H8,$I8,IF(11>=$F8,$G8,$E8))) | U8: =IF(OR(12<$C8,12>$D8),0,IF(12>=$H8,$I8,IF(12>=$F8,$G8,$E8))) | V8: =IF(OR(13<$C8,13>$D8),0,IF(13>=$H8,$I8,IF(13>=$F8,$G8,$E8))) | W8: =IF(OR(14<$C8,14>$D8),0,IF(14>=$H8,$I8,IF(14>=$F8,$G8,$E8))) | X8: =IF(OR(15<$C8,15>$D8),0,IF(15>=$H8,$I8,IF(15>=$F8,$G8,$E8))) | Y8: =IF(OR(16<$C8,16>$D8),0,IF(16>=$H8,$I8,IF(16>=$F8,$G8,$E8))) | Z8: =IF(OR(17<$C8,17>$D8),0,IF(17>=$H8,$I8,IF(17>=$F8,$G8,$E8))) | AA8: =IF(OR(18<$C8,18>$D8),0,IF(18>=$H8,$I8,IF(18>=$F8,$G8,$E8))) | AB8: =IF(OR(19<$C8,19>$D8),0,IF(19>=$H8,$I8,IF(19>=$F8,$G8,$E8))) | AC8: =IF(OR(20<$C8,20>$D8),0,IF(20>=$H8,$I8,IF(20>=$F8,$G8,$E8))) | AD8: =IF(OR(21<$C8,21>$D8),0,IF(21>=$H8,$I8,IF(21>=$F8,$G8,$E8))) | AE8: =IF(OR(22<$C8,22>$D8),0,IF(22>=$H8,$I8,IF(22>=$F8,$G8,$E8))) | AF8: =IF(OR(23<$C8,23>$D8),0,IF(23>=$H8,$I8,IF(23>=$F8,$G8,$E8))) | AG8: =IF(OR(24<$C8,24>$D8),0,IF(24>=$H8,$I8,IF(24>=$F8,$G8,$E8))) | AH8: =IF(OR(25<$C8,25>$D8),0,IF(25>=$H8,$I8,IF(25>=$F8,$G8,$E8))) | AI8: =IF(OR(26<$C8,26>$D8),0,IF(26>=$H8,$I8,IF(26>=$F8,$G8,$E8))) | AJ8: =IF(OR(27<$C8,27>$D8),0,IF(27>=$H8,$I8,IF(27>=$F8,$G8,$E8))) | AK8: =IF(OR(28<$C8,28>$D8),0,IF(28>=$H8,$I8,IF(28>=$F8,$G8,$E8))) | AL8: =IF(OR(29<$C8,29>$D8),0,IF(29>=$H8,$I8,IF(29>=$F8,$G8,$E8))) | AM8: =IF(OR(30<$C8,30>$D8),0,IF(30>=$H8,$I8,IF(30>=$F8,$G8,$E8))) | AN8: =IF(OR(31<$C8,31>$D8),0,IF(31>=$H8,$I8,IF(31>=$F8,$G8,$E8))) | AO8: =IF(OR(32<$C8,32>$D8),0,IF(32>=$H8,$I8,IF(32>=$F8,$G8,$E8))) | AP8: =IF(OR(33<$C8,33>$D8),0,IF(33>=$H8,$I8,IF(33>=$F8,$G8,$E8))) | AQ8: =IF(OR(34<$C8,34>$D8),0,IF(34>=$H8,$I8,IF(34>=$F8,$G8,$E8))) | AR8: =IF(OR(35<$C8,35>$D8),0,IF(35>=$H8,$I8,IF(35>=$F8,$G8,$E8))) | AS8: =IF(OR(36<$C8,36>$D8),0,IF(36>=$H8,$I8,IF(36>=$F8,$G8,$E8)))
B9: Senior full-stack engineer | C9: 1 | D9: 999 | E9: 9200 | F9: 999 | G9: 9200 | H9: 999 | I9: 9200 | J9: =IF(OR(1<$C9,1>$D9),0,IF(1>=$H9,$I9,IF(1>=$F9,$G9,$E9))) | K9: =IF(OR(2<$C9,2>$D9),0,IF(2>=$H9,$I9,IF(2>=$F9,$G9,$E9))) | L9: =IF(OR(3<$C9,3>$D9),0,IF(3>=$H9,$I9,IF(3>=$F9,$G9,$E9))) | M9: =IF(OR(4<$C9,4>$D9),0,IF(4>=$H9,$I9,IF(4>=$F9,$G9,$E9))) | N9: =IF(OR(5<$C9,5>$D9),0,IF(5>=$H9,$I9,IF(5>=$F9,$G9,$E9))) | O9: =IF(OR(6<$C9,6>$D9),0,IF(6>=$H9,$I9,IF(6>=$F9,$G9,$E9))) | P9: =IF(OR(7<$C9,7>$D9),0,IF(7>=$H9,$I9,IF(7>=$F9,$G9,$E9))) | Q9: =IF(OR(8<$C9,8>$D9),0,IF(8>=$H9,$I9,IF(8>=$F9,$G9,$E9))) | R9: =IF(OR(9<$C9,9>$D9),0,IF(9>=$H9,$I9,IF(9>=$F9,$G9,$E9))) | S9: =IF(OR(10<$C9,10>$D9),0,IF(10>=$H9,$I9,IF(10>=$F9,$G9,$E9))) | T9: =IF(OR(11<$C9,11>$D9),0,IF(11>=$H9,$I9,IF(11>=$F9,$G9,$E9))) | U9: =IF(OR(12<$C9,12>$D9),0,IF(12>=$H9,$I9,IF(12>=$F9,$G9,$E9))) | V9: =IF(OR(13<$C9,13>$D9),0,IF(13>=$H9,$I9,IF(13>=$F9,$G9,$E9))) | W9: =IF(OR(14<$C9,14>$D9),0,IF(14>=$H9,$I9,IF(14>=$F9,$G9,$E9))) | X9: =IF(OR(15<$C9,15>$D9),0,IF(15>=$H9,$I9,IF(15>=$F9,$G9,$E9))) | Y9: =IF(OR(16<$C9,16>$D9),0,IF(16>=$H9,$I9,IF(16>=$F9,$G9,$E9))) | Z9: =IF(OR(17<$C9,17>$D9),0,IF(17>=$H9,$I9,IF(17>=$F9,$G9,$E9))) | AA9: =IF(OR(18<$C9,18>$D9),0,IF(18>=$H9,$I9,IF(18>=$F9,$G9,$E9))) | AB9: =IF(OR(19<$C9,19>$D9),0,IF(19>=$H9,$I9,IF(19>=$F9,$G9,$E9))) | AC9: =IF(OR(20<$C9,20>$D9),0,IF(20>=$H9,$I9,IF(20>=$F9,$G9,$E9))) | AD9: =IF(OR(21<$C9,21>$D9),0,IF(21>=$H9,$I9,IF(21>=$F9,$G9,$E9))) | AE9: =IF(OR(22<$C9,22>$D9),0,IF(22>=$H9,$I9,IF(22>=$F9,$G9,$E9))) | AF9: =IF(OR(23<$C9,23>$D9),0,IF(23>=$H9,$I9,IF(23>=$F9,$G9,$E9))) | AG9: =IF(OR(24<$C9,24>$D9),0,IF(24>=$H9,$I9,IF(24>=$F9,$G9,$E9))) | AH9: =IF(OR(25<$C9,25>$D9),0,IF(25>=$H9,$I9,IF(25>=$F9,$G9,$E9))) | AI9: =IF(OR(26<$C9,26>$D9),0,IF(26>=$H9,$I9,IF(26>=$F9,$G9,$E9))) | AJ9: =IF(OR(27<$C9,27>$D9),0,IF(27>=$H9,$I9,IF(27>=$F9,$G9,$E9))) | AK9: =IF(OR(28<$C9,28>$D9),0,IF(28>=$H9,$I9,IF(28>=$F9,$G9,$E9))) | AL9: =IF(OR(29<$C9,29>$D9),0,IF(29>=$H9,$I9,IF(29>=$F9,$G9,$E9))) | AM9: =IF(OR(30<$C9,30>$D9),0,IF(30>=$H9,$I9,IF(30>=$F9,$G9,$E9))) | AN9: =IF(OR(31<$C9,31>$D9),0,IF(31>=$H9,$I9,IF(31>=$F9,$G9,$E9))) | AO9: =IF(OR(32<$C9,32>$D9),0,IF(32>=$H9,$I9,IF(32>=$F9,$G9,$E9))) | AP9: =IF(OR(33<$C9,33>$D9),0,IF(33>=$H9,$I9,IF(33>=$F9,$G9,$E9))) | AQ9: =IF(OR(34<$C9,34>$D9),0,IF(34>=$H9,$I9,IF(34>=$F9,$G9,$E9))) | AR9: =IF(OR(35<$C9,35>$D9),0,IF(35>=$H9,$I9,IF(35>=$F9,$G9,$E9))) | AS9: =IF(OR(36<$C9,36>$D9),0,IF(36>=$H9,$I9,IF(36>=$F9,$G9,$E9)))
B10: Registered Dietitian (PT to FT) | C10: 1 | D10: 999 | E10: 3800 | F10: 10 | G10: 6700 | H10: 999 | I10: 6700 | J10: =IF(OR(1<$C10,1>$D10),0,IF(1>=$H10,$I10,IF(1>=$F10,$G10,$E10))) | K10: =IF(OR(2<$C10,2>$D10),0,IF(2>=$H10,$I10,IF(2>=$F10,$G10,$E10))) | L10: =IF(OR(3<$C10,3>$D10),0,IF(3>=$H10,$I10,IF(3>=$F10,$G10,$E10))) | M10: =IF(OR(4<$C10,4>$D10),0,IF(4>=$H10,$I10,IF(4>=$F10,$G10,$E10))) | N10: =IF(OR(5<$C10,5>$D10),0,IF(5>=$H10,$I10,IF(5>=$F10,$G10,$E10))) | O10: =IF(OR(6<$C10,6>$D10),0,IF(6>=$H10,$I10,IF(6>=$F10,$G10,$E10))) | P10: =IF(OR(7<$C10,7>$D10),0,IF(7>=$H10,$I10,IF(7>=$F10,$G10,$E10))) | Q10: =IF(OR(8<$C10,8>$D10),0,IF(8>=$H10,$I10,IF(8>=$F10,$G10,$E10))) | R10: =IF(OR(9<$C10,9>$D10),0,IF(9>=$H10,$I10,IF(9>=$F10,$G10,$E10))) | S10: =IF(OR(10<$C10,10>$D10),0,IF(10>=$H10,$I10,IF(10>=$F10,$G10,$E10))) | T10: =IF(OR(11<$C10,11>$D10),0,IF(11>=$H10,$I10,IF(11>=$F10,$G10,$E10))) | U10: =IF(OR(12<$C10,12>$D10),0,IF(12>=$H10,$I10,IF(12>=$F10,$G10,$E10))) | V10: =IF(OR(13<$C10,13>$D10),0,IF(13>=$H10,$I10,IF(13>=$F10,$G10,$E10))) | W10: =IF(OR(14<$C10,14>$D10),0,IF(14>=$H10,$I10,IF(14>=$F10,$G10,$E10))) | X10: =IF(OR(15<$C10,15>$D10),0,IF(15>=$H10,$I10,IF(15>=$F10,$G10,$E10))) | Y10: =IF(OR(16<$C10,16>$D10),0,IF(16>=$H10,$I10,IF(16>=$F10,$G10,$E10))) | Z10: =IF(OR(17<$C10,17>$D10),0,IF(17>=$H10,$I10,IF(17>=$F10,$G10,$E10))) | AA10: =IF(OR(18<$C10,18>$D10),0,IF(18>=$H10,$I10,IF(18>=$F10,$G10,$E10))) | AB10: =IF(OR(19<$C10,19>$D10),0,IF(19>=$H10,$I10,IF(19>=$F10,$G10,$E10))) | AC10: =IF(OR(20<$C10,20>$D10),0,IF(20>=$H10,$I10,IF(20>=$F10,$G10,$E10))) | AD10: =IF(OR(21<$C10,21>$D10),0,IF(21>=$H10,$I10,IF(21>=$F10,$G10,$E10))) | AE10: =IF(OR(22<$C10,22>$D10),0,IF(22>=$H10,$I10,IF(22>=$F10,$G10,$E10))) | AF10: =IF(OR(23<$C10,23>$D10),0,IF(23>=$H10,$I10,IF(23>=$F10,$G10,$E10))) | AG10: =IF(OR(24<$C10,24>$D10),0,IF(24>=$H10,$I10,IF(24>=$F10,$G10,$E10))) | AH10: =IF(OR(25<$C10,25>$D10),0,IF(25>=$H10,$I10,IF(25>=$F10,$G10,$E10))) | AI10: =IF(OR(26<$C10,26>$D10),0,IF(26>=$H10,$I10,IF(26>=$F10,$G10,$E10))) | AJ10: =IF(OR(27<$C10,27>$D10),0,IF(27>=$H10,$I10,IF(27>=$F10,$G10,$E10))) | AK10: =IF(OR(28<$C10,28>$D10),0,IF(28>=$H10,$I10,IF(28>=$F10,$G10,$E10))) | AL10: =IF(OR(29<$C10,29>$D10),0,IF(29>=$H10,$I10,IF(29>=$F10,$G10,$E10))) | AM10: =IF(OR(30<$C10,30>$D10),0,IF(30>=$H10,$I10,IF(30>=$F10,$G10,$E10))) | AN10: =IF(OR(31<$C10,31>$D10),0,IF(31>=$H10,$I10,IF(31>=$F10,$G10,$E10))) | AO10: =IF(OR(32<$C10,32>$D10),0,IF(32>=$H10,$I10,IF(32>=$F10,$G10,$E10))) | AP10: =IF(OR(33<$C10,33>$D10),0,IF(33>=$H10,$I10,IF(33>=$F10,$G10,$E10))) | AQ10: =IF(OR(34<$C10,34>$D10),0,IF(34>=$H10,$I10,IF(34>=$F10,$G10,$E10))) | AR10: =IF(OR(35<$C10,35>$D10),0,IF(35>=$H10,$I10,IF(35>=$F10,$G10,$E10))) | AS10: =IF(OR(36<$C10,36>$D10),0,IF(36>=$H10,$I10,IF(36>=$F10,$G10,$E10)))
B11: Product designer (contract to FT) | C11: 2 | D11: 999 | E11: 5500 | F11: 12 | G11: 6300 | H11: 999 | I11: 6300 | J11: =IF(OR(1<$C11,1>$D11),0,IF(1>=$H11,$I11,IF(1>=$F11,$G11,$E11))) | K11: =IF(OR(2<$C11,2>$D11),0,IF(2>=$H11,$I11,IF(2>=$F11,$G11,$E11))) | L11: =IF(OR(3<$C11,3>$D11),0,IF(3>=$H11,$I11,IF(3>=$F11,$G11,$E11))) | M11: =IF(OR(4<$C11,4>$D11),0,IF(4>=$H11,$I11,IF(4>=$F11,$G11,$E11))) | N11: =IF(OR(5<$C11,5>$D11),0,IF(5>=$H11,$I11,IF(5>=$F11,$G11,$E11))) | O11: =IF(OR(6<$C11,6>$D11),0,IF(6>=$H11,$I11,IF(6>=$F11,$G11,$E11))) | P11: =IF(OR(7<$C11,7>$D11),0,IF(7>=$H11,$I11,IF(7>=$F11,$G11,$E11))) | Q11: =IF(OR(8<$C11,8>$D11),0,IF(8>=$H11,$I11,IF(8>=$F11,$G11,$E11))) | R11: =IF(OR(9<$C11,9>$D11),0,IF(9>=$H11,$I11,IF(9>=$F11,$G11,$E11))) | S11: =IF(OR(10<$C11,10>$D11),0,IF(10>=$H11,$I11,IF(10>=$F11,$G11,$E11))) | T11: =IF(OR(11<$C11,11>$D11),0,IF(11>=$H11,$I11,IF(11>=$F11,$G11,$E11))) | U11: =IF(OR(12<$C11,12>$D11),0,IF(12>=$H11,$I11,IF(12>=$F11,$G11,$E11))) | V11: =IF(OR(13<$C11,13>$D11),0,IF(13>=$H11,$I11,IF(13>=$F11,$G11,$E11))) | W11: =IF(OR(14<$C11,14>$D11),0,IF(14>=$H11,$I11,IF(14>=$F11,$G11,$E11))) | X11: =IF(OR(15<$C11,15>$D11),0,IF(15>=$H11,$I11,IF(15>=$F11,$G11,$E11))) | Y11: =IF(OR(16<$C11,16>$D11),0,IF(16>=$H11,$I11,IF(16>=$F11,$G11,$E11))) | Z11: =IF(OR(17<$C11,17>$D11),0,IF(17>=$H11,$I11,IF(17>=$F11,$G11,$E11))) | AA11: =IF(OR(18<$C11,18>$D11),0,IF(18>=$H11,$I11,IF(18>=$F11,$G11,$E11))) | AB11: =IF(OR(19<$C11,19>$D11),0,IF(19>=$H11,$I11,IF(19>=$F11,$G11,$E11))) | AC11: =IF(OR(20<$C11,20>$D11),0,IF(20>=$H11,$I11,IF(20>=$F11,$G11,$E11))) | AD11: =IF(OR(21<$C11,21>$D11),0,IF(21>=$H11,$I11,IF(21>=$F11,$G11,$E11))) | AE11: =IF(OR(22<$C11,22>$D11),0,IF(22>=$H11,$I11,IF(22>=$F11,$G11,$E11))) | AF11: =IF(OR(23<$C11,23>$D11),0,IF(23>=$H11,$I11,IF(23>=$F11,$G11,$E11))) | AG11: =IF(OR(24<$C11,24>$D11),0,IF(24>=$H11,$I11,IF(24>=$F11,$G11,$E11))) | AH11: =IF(OR(25<$C11,25>$D11),0,IF(25>=$H11,$I11,IF(25>=$F11,$G11,$E11))) | AI11: =IF(OR(26<$C11,26>$D11),0,IF(26>=$H11,$I11,IF(26>=$F11,$G11,$E11))) | AJ11: =IF(OR(27<$C11,27>$D11),0,IF(27>=$H11,$I11,IF(27>=$F11,$G11,$E11))) | AK11: =IF(OR(28<$C11,28>$D11),0,IF(28>=$H11,$I11,IF(28>=$F11,$G11,$E11))) | AL11: =IF(OR(29<$C11,29>$D11),0,IF(29>=$H11,$I11,IF(29>=$F11,$G11,$E11))) | AM11: =IF(OR(30<$C11,30>$D11),0,IF(30>=$H11,$I11,IF(30>=$F11,$G11,$E11))) | AN11: =IF(OR(31<$C11,31>$D11),0,IF(31>=$H11,$I11,IF(31>=$F11,$G11,$E11))) | AO11: =IF(OR(32<$C11,32>$D11),0,IF(32>=$H11,$I11,IF(32>=$F11,$G11,$E11))) | AP11: =IF(OR(33<$C11,33>$D11),0,IF(33>=$H11,$I11,IF(33>=$F11,$G11,$E11))) | AQ11: =IF(OR(34<$C11,34>$D11),0,IF(34>=$H11,$I11,IF(34>=$F11,$G11,$E11))) | AR11: =IF(OR(35<$C11,35>$D11),0,IF(35>=$H11,$I11,IF(35>=$F11,$G11,$E11))) | AS11: =IF(OR(36<$C11,36>$D11),0,IF(36>=$H11,$I11,IF(36>=$F11,$G11,$E11)))
B12: Full-stack engineer #2 | C12: 3 | D12: 999 | E12: 8000 | F12: 999 | G12: 8000 | H12: 999 | I12: 8000 | J12: =IF(OR(1<$C12,1>$D12),0,IF(1>=$H12,$I12,IF(1>=$F12,$G12,$E12))) | K12: =IF(OR(2<$C12,2>$D12),0,IF(2>=$H12,$I12,IF(2>=$F12,$G12,$E12))) | L12: =IF(OR(3<$C12,3>$D12),0,IF(3>=$H12,$I12,IF(3>=$F12,$G12,$E12))) | M12: =IF(OR(4<$C12,4>$D12),0,IF(4>=$H12,$I12,IF(4>=$F12,$G12,$E12))) | N12: =IF(OR(5<$C12,5>$D12),0,IF(5>=$H12,$I12,IF(5>=$F12,$G12,$E12))) | O12: =IF(OR(6<$C12,6>$D12),0,IF(6>=$H12,$I12,IF(6>=$F12,$G12,$E12))) | P12: =IF(OR(7<$C12,7>$D12),0,IF(7>=$H12,$I12,IF(7>=$F12,$G12,$E12))) | Q12: =IF(OR(8<$C12,8>$D12),0,IF(8>=$H12,$I12,IF(8>=$F12,$G12,$E12))) | R12: =IF(OR(9<$C12,9>$D12),0,IF(9>=$H12,$I12,IF(9>=$F12,$G12,$E12))) | S12: =IF(OR(10<$C12,10>$D12),0,IF(10>=$H12,$I12,IF(10>=$F12,$G12,$E12))) | T12: =IF(OR(11<$C12,11>$D12),0,IF(11>=$H12,$I12,IF(11>=$F12,$G12,$E12))) | U12: =IF(OR(12<$C12,12>$D12),0,IF(12>=$H12,$I12,IF(12>=$F12,$G12,$E12))) | V12: =IF(OR(13<$C12,13>$D12),0,IF(13>=$H12,$I12,IF(13>=$F12,$G12,$E12))) | W12: =IF(OR(14<$C12,14>$D12),0,IF(14>=$H12,$I12,IF(14>=$F12,$G12,$E12))) | X12: =IF(OR(15<$C12,15>$D12),0,IF(15>=$H12,$I12,IF(15>=$F12,$G12,$E12))) | Y12: =IF(OR(16<$C12,16>$D12),0,IF(16>=$H12,$I12,IF(16>=$F12,$G12,$E12))) | Z12: =IF(OR(17<$C12,17>$D12),0,IF(17>=$H12,$I12,IF(17>=$F12,$G12,$E12))) | AA12: =IF(OR(18<$C12,18>$D12),0,IF(18>=$H12,$I12,IF(18>=$F12,$G12,$E12))) | AB12: =IF(OR(19<$C12,19>$D12),0,IF(19>=$H12,$I12,IF(19>=$F12,$G12,$E12))) | AC12: =IF(OR(20<$C12,20>$D12),0,IF(20>=$H12,$I12,IF(20>=$F12,$G12,$E12))) | AD12: =IF(OR(21<$C12,21>$D12),0,IF(21>=$H12,$I12,IF(21>=$F12,$G12,$E12))) | AE12: =IF(OR(22<$C12,22>$D12),0,IF(22>=$H12,$I12,IF(22>=$F12,$G12,$E12))) | AF12: =IF(OR(23<$C12,23>$D12),0,IF(23>=$H12,$I12,IF(23>=$F12,$G12,$E12))) | AG12: =IF(OR(24<$C12,24>$D12),0,IF(24>=$H12,$I12,IF(24>=$F12,$G12,$E12))) | AH12: =IF(OR(25<$C12,25>$D12),0,IF(25>=$H12,$I12,IF(25>=$F12,$G12,$E12))) | AI12: =IF(OR(26<$C12,26>$D12),0,IF(26>=$H12,$I12,IF(26>=$F12,$G12,$E12))) | AJ12: =IF(OR(27<$C12,27>$D12),0,IF(27>=$H12,$I12,IF(27>=$F12,$G12,$E12))) | AK12: =IF(OR(28<$C12,28>$D12),0,IF(28>=$H12,$I12,IF(28>=$F12,$G12,$E12))) | AL12: =IF(OR(29<$C12,29>$D12),0,IF(29>=$H12,$I12,IF(29>=$F12,$G12,$E12))) | AM12: =IF(OR(30<$C12,30>$D12),0,IF(30>=$H12,$I12,IF(30>=$F12,$G12,$E12))) | AN12: =IF(OR(31<$C12,31>$D12),0,IF(31>=$H12,$I12,IF(31>=$F12,$G12,$E12))) | AO12: =IF(OR(32<$C12,32>$D12),0,IF(32>=$H12,$I12,IF(32>=$F12,$G12,$E12))) | AP12: =IF(OR(33<$C12,33>$D12),0,IF(33>=$H12,$I12,IF(33>=$F12,$G12,$E12))) | AQ12: =IF(OR(34<$C12,34>$D12),0,IF(34>=$H12,$I12,IF(34>=$F12,$G12,$E12))) | AR12: =IF(OR(35<$C12,35>$D12),0,IF(35>=$H12,$I12,IF(35>=$F12,$G12,$E12))) | AS12: =IF(OR(36<$C12,36>$D12),0,IF(36>=$H12,$I12,IF(36>=$F12,$G12,$E12)))
B13: Growth and content lead | C13: 5 | D13: 999 | E13: 7900 | F13: 999 | G13: 7900 | H13: 999 | I13: 7900 | J13: =IF(OR(1<$C13,1>$D13),0,IF(1>=$H13,$I13,IF(1>=$F13,$G13,$E13))) | K13: =IF(OR(2<$C13,2>$D13),0,IF(2>=$H13,$I13,IF(2>=$F13,$G13,$E13))) | L13: =IF(OR(3<$C13,3>$D13),0,IF(3>=$H13,$I13,IF(3>=$F13,$G13,$E13))) | M13: =IF(OR(4<$C13,4>$D13),0,IF(4>=$H13,$I13,IF(4>=$F13,$G13,$E13))) | N13: =IF(OR(5<$C13,5>$D13),0,IF(5>=$H13,$I13,IF(5>=$F13,$G13,$E13))) | O13: =IF(OR(6<$C13,6>$D13),0,IF(6>=$H13,$I13,IF(6>=$F13,$G13,$E13))) | P13: =IF(OR(7<$C13,7>$D13),0,IF(7>=$H13,$I13,IF(7>=$F13,$G13,$E13))) | Q13: =IF(OR(8<$C13,8>$D13),0,IF(8>=$H13,$I13,IF(8>=$F13,$G13,$E13))) | R13: =IF(OR(9<$C13,9>$D13),0,IF(9>=$H13,$I13,IF(9>=$F13,$G13,$E13))) | S13: =IF(OR(10<$C13,10>$D13),0,IF(10>=$H13,$I13,IF(10>=$F13,$G13,$E13))) | T13: =IF(OR(11<$C13,11>$D13),0,IF(11>=$H13,$I13,IF(11>=$F13,$G13,$E13))) | U13: =IF(OR(12<$C13,12>$D13),0,IF(12>=$H13,$I13,IF(12>=$F13,$G13,$E13))) | V13: =IF(OR(13<$C13,13>$D13),0,IF(13>=$H13,$I13,IF(13>=$F13,$G13,$E13))) | W13: =IF(OR(14<$C13,14>$D13),0,IF(14>=$H13,$I13,IF(14>=$F13,$G13,$E13))) | X13: =IF(OR(15<$C13,15>$D13),0,IF(15>=$H13,$I13,IF(15>=$F13,$G13,$E13))) | Y13: =IF(OR(16<$C13,16>$D13),0,IF(16>=$H13,$I13,IF(16>=$F13,$G13,$E13))) | Z13: =IF(OR(17<$C13,17>$D13),0,IF(17>=$H13,$I13,IF(17>=$F13,$G13,$E13))) | AA13: =IF(OR(18<$C13,18>$D13),0,IF(18>=$H13,$I13,IF(18>=$F13,$G13,$E13))) | AB13: =IF(OR(19<$C13,19>$D13),0,IF(19>=$H13,$I13,IF(19>=$F13,$G13,$E13))) | AC13: =IF(OR(20<$C13,20>$D13),0,IF(20>=$H13,$I13,IF(20>=$F13,$G13,$E13))) | AD13: =IF(OR(21<$C13,21>$D13),0,IF(21>=$H13,$I13,IF(21>=$F13,$G13,$E13))) | AE13: =IF(OR(22<$C13,22>$D13),0,IF(22>=$H13,$I13,IF(22>=$F13,$G13,$E13))) | AF13: =IF(OR(23<$C13,23>$D13),0,IF(23>=$H13,$I13,IF(23>=$F13,$G13,$E13))) | AG13: =IF(OR(24<$C13,24>$D13),0,IF(24>=$H13,$I13,IF(24>=$F13,$G13,$E13))) | AH13: =IF(OR(25<$C13,25>$D13),0,IF(25>=$H13,$I13,IF(25>=$F13,$G13,$E13))) | AI13: =IF(OR(26<$C13,26>$D13),0,IF(26>=$H13,$I13,IF(26>=$F13,$G13,$E13))) | AJ13: =IF(OR(27<$C13,27>$D13),0,IF(27>=$H13,$I13,IF(27>=$F13,$G13,$E13))) | AK13: =IF(OR(28<$C13,28>$D13),0,IF(28>=$H13,$I13,IF(28>=$F13,$G13,$E13))) | AL13: =IF(OR(29<$C13,29>$D13),0,IF(29>=$H13,$I13,IF(29>=$F13,$G13,$E13))) | AM13: =IF(OR(30<$C13,30>$D13),0,IF(30>=$H13,$I13,IF(30>=$F13,$G13,$E13))) | AN13: =IF(OR(31<$C13,31>$D13),0,IF(31>=$H13,$I13,IF(31>=$F13,$G13,$E13))) | AO13: =IF(OR(32<$C13,32>$D13),0,IF(32>=$H13,$I13,IF(32>=$F13,$G13,$E13))) | AP13: =IF(OR(33<$C13,33>$D13),0,IF(33>=$H13,$I13,IF(33>=$F13,$G13,$E13))) | AQ13: =IF(OR(34<$C13,34>$D13),0,IF(34>=$H13,$I13,IF(34>=$F13,$G13,$E13))) | AR13: =IF(OR(35<$C13,35>$D13),0,IF(35>=$H13,$I13,IF(35>=$F13,$G13,$E13))) | AS13: =IF(OR(36<$C13,36>$D13),0,IF(36>=$H13,$I13,IF(36>=$F13,$G13,$E13)))
B14: Clinical and regulatory lead (PT) | C14: 6 | D14: 999 | E14: 5800 | F14: 999 | G14: 5800 | H14: 999 | I14: 5800 | J14: =IF(OR(1<$C14,1>$D14),0,IF(1>=$H14,$I14,IF(1>=$F14,$G14,$E14))) | K14: =IF(OR(2<$C14,2>$D14),0,IF(2>=$H14,$I14,IF(2>=$F14,$G14,$E14))) | L14: =IF(OR(3<$C14,3>$D14),0,IF(3>=$H14,$I14,IF(3>=$F14,$G14,$E14))) | M14: =IF(OR(4<$C14,4>$D14),0,IF(4>=$H14,$I14,IF(4>=$F14,$G14,$E14))) | N14: =IF(OR(5<$C14,5>$D14),0,IF(5>=$H14,$I14,IF(5>=$F14,$G14,$E14))) | O14: =IF(OR(6<$C14,6>$D14),0,IF(6>=$H14,$I14,IF(6>=$F14,$G14,$E14))) | P14: =IF(OR(7<$C14,7>$D14),0,IF(7>=$H14,$I14,IF(7>=$F14,$G14,$E14))) | Q14: =IF(OR(8<$C14,8>$D14),0,IF(8>=$H14,$I14,IF(8>=$F14,$G14,$E14))) | R14: =IF(OR(9<$C14,9>$D14),0,IF(9>=$H14,$I14,IF(9>=$F14,$G14,$E14))) | S14: =IF(OR(10<$C14,10>$D14),0,IF(10>=$H14,$I14,IF(10>=$F14,$G14,$E14))) | T14: =IF(OR(11<$C14,11>$D14),0,IF(11>=$H14,$I14,IF(11>=$F14,$G14,$E14))) | U14: =IF(OR(12<$C14,12>$D14),0,IF(12>=$H14,$I14,IF(12>=$F14,$G14,$E14))) | V14: =IF(OR(13<$C14,13>$D14),0,IF(13>=$H14,$I14,IF(13>=$F14,$G14,$E14))) | W14: =IF(OR(14<$C14,14>$D14),0,IF(14>=$H14,$I14,IF(14>=$F14,$G14,$E14))) | X14: =IF(OR(15<$C14,15>$D14),0,IF(15>=$H14,$I14,IF(15>=$F14,$G14,$E14))) | Y14: =IF(OR(16<$C14,16>$D14),0,IF(16>=$H14,$I14,IF(16>=$F14,$G14,$E14))) | Z14: =IF(OR(17<$C14,17>$D14),0,IF(17>=$H14,$I14,IF(17>=$F14,$G14,$E14))) | AA14: =IF(OR(18<$C14,18>$D14),0,IF(18>=$H14,$I14,IF(18>=$F14,$G14,$E14))) | AB14: =IF(OR(19<$C14,19>$D14),0,IF(19>=$H14,$I14,IF(19>=$F14,$G14,$E14))) | AC14: =IF(OR(20<$C14,20>$D14),0,IF(20>=$H14,$I14,IF(20>=$F14,$G14,$E14))) | AD14: =IF(OR(21<$C14,21>$D14),0,IF(21>=$H14,$I14,IF(21>=$F14,$G14,$E14))) | AE14: =IF(OR(22<$C14,22>$D14),0,IF(22>=$H14,$I14,IF(22>=$F14,$G14,$E14))) | AF14: =IF(OR(23<$C14,23>$D14),0,IF(23>=$H14,$I14,IF(23>=$F14,$G14,$E14))) | AG14: =IF(OR(24<$C14,24>$D14),0,IF(24>=$H14,$I14,IF(24>=$F14,$G14,$E14))) | AH14: =IF(OR(25<$C14,25>$D14),0,IF(25>=$H14,$I14,IF(25>=$F14,$G14,$E14))) | AI14: =IF(OR(26<$C14,26>$D14),0,IF(26>=$H14,$I14,IF(26>=$F14,$G14,$E14))) | AJ14: =IF(OR(27<$C14,27>$D14),0,IF(27>=$H14,$I14,IF(27>=$F14,$G14,$E14))) | AK14: =IF(OR(28<$C14,28>$D14),0,IF(28>=$H14,$I14,IF(28>=$F14,$G14,$E14))) | AL14: =IF(OR(29<$C14,29>$D14),0,IF(29>=$H14,$I14,IF(29>=$F14,$G14,$E14))) | AM14: =IF(OR(30<$C14,30>$D14),0,IF(30>=$H14,$I14,IF(30>=$F14,$G14,$E14))) | AN14: =IF(OR(31<$C14,31>$D14),0,IF(31>=$H14,$I14,IF(31>=$F14,$G14,$E14))) | AO14: =IF(OR(32<$C14,32>$D14),0,IF(32>=$H14,$I14,IF(32>=$F14,$G14,$E14))) | AP14: =IF(OR(33<$C14,33>$D14),0,IF(33>=$H14,$I14,IF(33>=$F14,$G14,$E14))) | AQ14: =IF(OR(34<$C14,34>$D14),0,IF(34>=$H14,$I14,IF(34>=$F14,$G14,$E14))) | AR14: =IF(OR(35<$C14,35>$D14),0,IF(35>=$H14,$I14,IF(35>=$F14,$G14,$E14))) | AS14: =IF(OR(36<$C14,36>$D14),0,IF(36>=$H14,$I14,IF(36>=$F14,$G14,$E14)))
B15: US medical director (PT, US rate) | C15: 7 | D15: 999 | E15: 10000 | F15: 999 | G15: 10000 | H15: 999 | I15: 10000 | J15: =IF(OR(1<$C15,1>$D15),0,IF(1>=$H15,$I15,IF(1>=$F15,$G15,$E15))) | K15: =IF(OR(2<$C15,2>$D15),0,IF(2>=$H15,$I15,IF(2>=$F15,$G15,$E15))) | L15: =IF(OR(3<$C15,3>$D15),0,IF(3>=$H15,$I15,IF(3>=$F15,$G15,$E15))) | M15: =IF(OR(4<$C15,4>$D15),0,IF(4>=$H15,$I15,IF(4>=$F15,$G15,$E15))) | N15: =IF(OR(5<$C15,5>$D15),0,IF(5>=$H15,$I15,IF(5>=$F15,$G15,$E15))) | O15: =IF(OR(6<$C15,6>$D15),0,IF(6>=$H15,$I15,IF(6>=$F15,$G15,$E15))) | P15: =IF(OR(7<$C15,7>$D15),0,IF(7>=$H15,$I15,IF(7>=$F15,$G15,$E15))) | Q15: =IF(OR(8<$C15,8>$D15),0,IF(8>=$H15,$I15,IF(8>=$F15,$G15,$E15))) | R15: =IF(OR(9<$C15,9>$D15),0,IF(9>=$H15,$I15,IF(9>=$F15,$G15,$E15))) | S15: =IF(OR(10<$C15,10>$D15),0,IF(10>=$H15,$I15,IF(10>=$F15,$G15,$E15))) | T15: =IF(OR(11<$C15,11>$D15),0,IF(11>=$H15,$I15,IF(11>=$F15,$G15,$E15))) | U15: =IF(OR(12<$C15,12>$D15),0,IF(12>=$H15,$I15,IF(12>=$F15,$G15,$E15))) | V15: =IF(OR(13<$C15,13>$D15),0,IF(13>=$H15,$I15,IF(13>=$F15,$G15,$E15))) | W15: =IF(OR(14<$C15,14>$D15),0,IF(14>=$H15,$I15,IF(14>=$F15,$G15,$E15))) | X15: =IF(OR(15<$C15,15>$D15),0,IF(15>=$H15,$I15,IF(15>=$F15,$G15,$E15))) | Y15: =IF(OR(16<$C15,16>$D15),0,IF(16>=$H15,$I15,IF(16>=$F15,$G15,$E15))) | Z15: =IF(OR(17<$C15,17>$D15),0,IF(17>=$H15,$I15,IF(17>=$F15,$G15,$E15))) | AA15: =IF(OR(18<$C15,18>$D15),0,IF(18>=$H15,$I15,IF(18>=$F15,$G15,$E15))) | AB15: =IF(OR(19<$C15,19>$D15),0,IF(19>=$H15,$I15,IF(19>=$F15,$G15,$E15))) | AC15: =IF(OR(20<$C15,20>$D15),0,IF(20>=$H15,$I15,IF(20>=$F15,$G15,$E15))) | AD15: =IF(OR(21<$C15,21>$D15),0,IF(21>=$H15,$I15,IF(21>=$F15,$G15,$E15))) | AE15: =IF(OR(22<$C15,22>$D15),0,IF(22>=$H15,$I15,IF(22>=$F15,$G15,$E15))) | AF15: =IF(OR(23<$C15,23>$D15),0,IF(23>=$H15,$I15,IF(23>=$F15,$G15,$E15))) | AG15: =IF(OR(24<$C15,24>$D15),0,IF(24>=$H15,$I15,IF(24>=$F15,$G15,$E15))) | AH15: =IF(OR(25<$C15,25>$D15),0,IF(25>=$H15,$I15,IF(25>=$F15,$G15,$E15))) | AI15: =IF(OR(26<$C15,26>$D15),0,IF(26>=$H15,$I15,IF(26>=$F15,$G15,$E15))) | AJ15: =IF(OR(27<$C15,27>$D15),0,IF(27>=$H15,$I15,IF(27>=$F15,$G15,$E15))) | AK15: =IF(OR(28<$C15,28>$D15),0,IF(28>=$H15,$I15,IF(28>=$F15,$G15,$E15))) | AL15: =IF(OR(29<$C15,29>$D15),0,IF(29>=$H15,$I15,IF(29>=$F15,$G15,$E15))) | AM15: =IF(OR(30<$C15,30>$D15),0,IF(30>=$H15,$I15,IF(30>=$F15,$G15,$E15))) | AN15: =IF(OR(31<$C15,31>$D15),0,IF(31>=$H15,$I15,IF(31>=$F15,$G15,$E15))) | AO15: =IF(OR(32<$C15,32>$D15),0,IF(32>=$H15,$I15,IF(32>=$F15,$G15,$E15))) | AP15: =IF(OR(33<$C15,33>$D15),0,IF(33>=$H15,$I15,IF(33>=$F15,$G15,$E15))) | AQ15: =IF(OR(34<$C15,34>$D15),0,IF(34>=$H15,$I15,IF(34>=$F15,$G15,$E15))) | AR15: =IF(OR(35<$C15,35>$D15),0,IF(35>=$H15,$I15,IF(35>=$F15,$G15,$E15))) | AS15: =IF(OR(36<$C15,36>$D15),0,IF(36>=$H15,$I15,IF(36>=$F15,$G15,$E15)))
B16: Support and community | C16: 8 | D16: 999 | E16: 3800 | F16: 20 | G16: 4200 | H16: 999 | I16: 4200 | J16: =IF(OR(1<$C16,1>$D16),0,IF(1>=$H16,$I16,IF(1>=$F16,$G16,$E16))) | K16: =IF(OR(2<$C16,2>$D16),0,IF(2>=$H16,$I16,IF(2>=$F16,$G16,$E16))) | L16: =IF(OR(3<$C16,3>$D16),0,IF(3>=$H16,$I16,IF(3>=$F16,$G16,$E16))) | M16: =IF(OR(4<$C16,4>$D16),0,IF(4>=$H16,$I16,IF(4>=$F16,$G16,$E16))) | N16: =IF(OR(5<$C16,5>$D16),0,IF(5>=$H16,$I16,IF(5>=$F16,$G16,$E16))) | O16: =IF(OR(6<$C16,6>$D16),0,IF(6>=$H16,$I16,IF(6>=$F16,$G16,$E16))) | P16: =IF(OR(7<$C16,7>$D16),0,IF(7>=$H16,$I16,IF(7>=$F16,$G16,$E16))) | Q16: =IF(OR(8<$C16,8>$D16),0,IF(8>=$H16,$I16,IF(8>=$F16,$G16,$E16))) | R16: =IF(OR(9<$C16,9>$D16),0,IF(9>=$H16,$I16,IF(9>=$F16,$G16,$E16))) | S16: =IF(OR(10<$C16,10>$D16),0,IF(10>=$H16,$I16,IF(10>=$F16,$G16,$E16))) | T16: =IF(OR(11<$C16,11>$D16),0,IF(11>=$H16,$I16,IF(11>=$F16,$G16,$E16))) | U16: =IF(OR(12<$C16,12>$D16),0,IF(12>=$H16,$I16,IF(12>=$F16,$G16,$E16))) | V16: =IF(OR(13<$C16,13>$D16),0,IF(13>=$H16,$I16,IF(13>=$F16,$G16,$E16))) | W16: =IF(OR(14<$C16,14>$D16),0,IF(14>=$H16,$I16,IF(14>=$F16,$G16,$E16))) | X16: =IF(OR(15<$C16,15>$D16),0,IF(15>=$H16,$I16,IF(15>=$F16,$G16,$E16))) | Y16: =IF(OR(16<$C16,16>$D16),0,IF(16>=$H16,$I16,IF(16>=$F16,$G16,$E16))) | Z16: =IF(OR(17<$C16,17>$D16),0,IF(17>=$H16,$I16,IF(17>=$F16,$G16,$E16))) | AA16: =IF(OR(18<$C16,18>$D16),0,IF(18>=$H16,$I16,IF(18>=$F16,$G16,$E16))) | AB16: =IF(OR(19<$C16,19>$D16),0,IF(19>=$H16,$I16,IF(19>=$F16,$G16,$E16))) | AC16: =IF(OR(20<$C16,20>$D16),0,IF(20>=$H16,$I16,IF(20>=$F16,$G16,$E16))) | AD16: =IF(OR(21<$C16,21>$D16),0,IF(21>=$H16,$I16,IF(21>=$F16,$G16,$E16))) | AE16: =IF(OR(22<$C16,22>$D16),0,IF(22>=$H16,$I16,IF(22>=$F16,$G16,$E16))) | AF16: =IF(OR(23<$C16,23>$D16),0,IF(23>=$H16,$I16,IF(23>=$F16,$G16,$E16))) | AG16: =IF(OR(24<$C16,24>$D16),0,IF(24>=$H16,$I16,IF(24>=$F16,$G16,$E16))) | AH16: =IF(OR(25<$C16,25>$D16),0,IF(25>=$H16,$I16,IF(25>=$F16,$G16,$E16))) | AI16: =IF(OR(26<$C16,26>$D16),0,IF(26>=$H16,$I16,IF(26>=$F16,$G16,$E16))) | AJ16: =IF(OR(27<$C16,27>$D16),0,IF(27>=$H16,$I16,IF(27>=$F16,$G16,$E16))) | AK16: =IF(OR(28<$C16,28>$D16),0,IF(28>=$H16,$I16,IF(28>=$F16,$G16,$E16))) | AL16: =IF(OR(29<$C16,29>$D16),0,IF(29>=$H16,$I16,IF(29>=$F16,$G16,$E16))) | AM16: =IF(OR(30<$C16,30>$D16),0,IF(30>=$H16,$I16,IF(30>=$F16,$G16,$E16))) | AN16: =IF(OR(31<$C16,31>$D16),0,IF(31>=$H16,$I16,IF(31>=$F16,$G16,$E16))) | AO16: =IF(OR(32<$C16,32>$D16),0,IF(32>=$H16,$I16,IF(32>=$F16,$G16,$E16))) | AP16: =IF(OR(33<$C16,33>$D16),0,IF(33>=$H16,$I16,IF(33>=$F16,$G16,$E16))) | AQ16: =IF(OR(34<$C16,34>$D16),0,IF(34>=$H16,$I16,IF(34>=$F16,$G16,$E16))) | AR16: =IF(OR(35<$C16,35>$D16),0,IF(35>=$H16,$I16,IF(35>=$F16,$G16,$E16))) | AS16: =IF(OR(36<$C16,36>$D16),0,IF(36>=$H16,$I16,IF(36>=$F16,$G16,$E16)))
B17: Engineer #3 | C17: 11 | D17: 999 | E17: 8600 | F17: 999 | G17: 8600 | H17: 999 | I17: 8600 | J17: =IF(OR(1<$C17,1>$D17),0,IF(1>=$H17,$I17,IF(1>=$F17,$G17,$E17))) | K17: =IF(OR(2<$C17,2>$D17),0,IF(2>=$H17,$I17,IF(2>=$F17,$G17,$E17))) | L17: =IF(OR(3<$C17,3>$D17),0,IF(3>=$H17,$I17,IF(3>=$F17,$G17,$E17))) | M17: =IF(OR(4<$C17,4>$D17),0,IF(4>=$H17,$I17,IF(4>=$F17,$G17,$E17))) | N17: =IF(OR(5<$C17,5>$D17),0,IF(5>=$H17,$I17,IF(5>=$F17,$G17,$E17))) | O17: =IF(OR(6<$C17,6>$D17),0,IF(6>=$H17,$I17,IF(6>=$F17,$G17,$E17))) | P17: =IF(OR(7<$C17,7>$D17),0,IF(7>=$H17,$I17,IF(7>=$F17,$G17,$E17))) | Q17: =IF(OR(8<$C17,8>$D17),0,IF(8>=$H17,$I17,IF(8>=$F17,$G17,$E17))) | R17: =IF(OR(9<$C17,9>$D17),0,IF(9>=$H17,$I17,IF(9>=$F17,$G17,$E17))) | S17: =IF(OR(10<$C17,10>$D17),0,IF(10>=$H17,$I17,IF(10>=$F17,$G17,$E17))) | T17: =IF(OR(11<$C17,11>$D17),0,IF(11>=$H17,$I17,IF(11>=$F17,$G17,$E17))) | U17: =IF(OR(12<$C17,12>$D17),0,IF(12>=$H17,$I17,IF(12>=$F17,$G17,$E17))) | V17: =IF(OR(13<$C17,13>$D17),0,IF(13>=$H17,$I17,IF(13>=$F17,$G17,$E17))) | W17: =IF(OR(14<$C17,14>$D17),0,IF(14>=$H17,$I17,IF(14>=$F17,$G17,$E17))) | X17: =IF(OR(15<$C17,15>$D17),0,IF(15>=$H17,$I17,IF(15>=$F17,$G17,$E17))) | Y17: =IF(OR(16<$C17,16>$D17),0,IF(16>=$H17,$I17,IF(16>=$F17,$G17,$E17))) | Z17: =IF(OR(17<$C17,17>$D17),0,IF(17>=$H17,$I17,IF(17>=$F17,$G17,$E17))) | AA17: =IF(OR(18<$C17,18>$D17),0,IF(18>=$H17,$I17,IF(18>=$F17,$G17,$E17))) | AB17: =IF(OR(19<$C17,19>$D17),0,IF(19>=$H17,$I17,IF(19>=$F17,$G17,$E17))) | AC17: =IF(OR(20<$C17,20>$D17),0,IF(20>=$H17,$I17,IF(20>=$F17,$G17,$E17))) | AD17: =IF(OR(21<$C17,21>$D17),0,IF(21>=$H17,$I17,IF(21>=$F17,$G17,$E17))) | AE17: =IF(OR(22<$C17,22>$D17),0,IF(22>=$H17,$I17,IF(22>=$F17,$G17,$E17))) | AF17: =IF(OR(23<$C17,23>$D17),0,IF(23>=$H17,$I17,IF(23>=$F17,$G17,$E17))) | AG17: =IF(OR(24<$C17,24>$D17),0,IF(24>=$H17,$I17,IF(24>=$F17,$G17,$E17))) | AH17: =IF(OR(25<$C17,25>$D17),0,IF(25>=$H17,$I17,IF(25>=$F17,$G17,$E17))) | AI17: =IF(OR(26<$C17,26>$D17),0,IF(26>=$H17,$I17,IF(26>=$F17,$G17,$E17))) | AJ17: =IF(OR(27<$C17,27>$D17),0,IF(27>=$H17,$I17,IF(27>=$F17,$G17,$E17))) | AK17: =IF(OR(28<$C17,28>$D17),0,IF(28>=$H17,$I17,IF(28>=$F17,$G17,$E17))) | AL17: =IF(OR(29<$C17,29>$D17),0,IF(29>=$H17,$I17,IF(29>=$F17,$G17,$E17))) | AM17: =IF(OR(30<$C17,30>$D17),0,IF(30>=$H17,$I17,IF(30>=$F17,$G17,$E17))) | AN17: =IF(OR(31<$C17,31>$D17),0,IF(31>=$H17,$I17,IF(31>=$F17,$G17,$E17))) | AO17: =IF(OR(32<$C17,32>$D17),0,IF(32>=$H17,$I17,IF(32>=$F17,$G17,$E17))) | AP17: =IF(OR(33<$C17,33>$D17),0,IF(33>=$H17,$I17,IF(33>=$F17,$G17,$E17))) | AQ17: =IF(OR(34<$C17,34>$D17),0,IF(34>=$H17,$I17,IF(34>=$F17,$G17,$E17))) | AR17: =IF(OR(35<$C17,35>$D17),0,IF(35>=$H17,$I17,IF(35>=$F17,$G17,$E17))) | AS17: =IF(OR(36<$C17,36>$D17),0,IF(36>=$H17,$I17,IF(36>=$F17,$G17,$E17)))
B18: Nutrition-data operations | C18: 12 | D18: 999 | E18: 5000 | F18: 999 | G18: 5000 | H18: 999 | I18: 5000 | J18: =IF(OR(1<$C18,1>$D18),0,IF(1>=$H18,$I18,IF(1>=$F18,$G18,$E18))) | K18: =IF(OR(2<$C18,2>$D18),0,IF(2>=$H18,$I18,IF(2>=$F18,$G18,$E18))) | L18: =IF(OR(3<$C18,3>$D18),0,IF(3>=$H18,$I18,IF(3>=$F18,$G18,$E18))) | M18: =IF(OR(4<$C18,4>$D18),0,IF(4>=$H18,$I18,IF(4>=$F18,$G18,$E18))) | N18: =IF(OR(5<$C18,5>$D18),0,IF(5>=$H18,$I18,IF(5>=$F18,$G18,$E18))) | O18: =IF(OR(6<$C18,6>$D18),0,IF(6>=$H18,$I18,IF(6>=$F18,$G18,$E18))) | P18: =IF(OR(7<$C18,7>$D18),0,IF(7>=$H18,$I18,IF(7>=$F18,$G18,$E18))) | Q18: =IF(OR(8<$C18,8>$D18),0,IF(8>=$H18,$I18,IF(8>=$F18,$G18,$E18))) | R18: =IF(OR(9<$C18,9>$D18),0,IF(9>=$H18,$I18,IF(9>=$F18,$G18,$E18))) | S18: =IF(OR(10<$C18,10>$D18),0,IF(10>=$H18,$I18,IF(10>=$F18,$G18,$E18))) | T18: =IF(OR(11<$C18,11>$D18),0,IF(11>=$H18,$I18,IF(11>=$F18,$G18,$E18))) | U18: =IF(OR(12<$C18,12>$D18),0,IF(12>=$H18,$I18,IF(12>=$F18,$G18,$E18))) | V18: =IF(OR(13<$C18,13>$D18),0,IF(13>=$H18,$I18,IF(13>=$F18,$G18,$E18))) | W18: =IF(OR(14<$C18,14>$D18),0,IF(14>=$H18,$I18,IF(14>=$F18,$G18,$E18))) | X18: =IF(OR(15<$C18,15>$D18),0,IF(15>=$H18,$I18,IF(15>=$F18,$G18,$E18))) | Y18: =IF(OR(16<$C18,16>$D18),0,IF(16>=$H18,$I18,IF(16>=$F18,$G18,$E18))) | Z18: =IF(OR(17<$C18,17>$D18),0,IF(17>=$H18,$I18,IF(17>=$F18,$G18,$E18))) | AA18: =IF(OR(18<$C18,18>$D18),0,IF(18>=$H18,$I18,IF(18>=$F18,$G18,$E18))) | AB18: =IF(OR(19<$C18,19>$D18),0,IF(19>=$H18,$I18,IF(19>=$F18,$G18,$E18))) | AC18: =IF(OR(20<$C18,20>$D18),0,IF(20>=$H18,$I18,IF(20>=$F18,$G18,$E18))) | AD18: =IF(OR(21<$C18,21>$D18),0,IF(21>=$H18,$I18,IF(21>=$F18,$G18,$E18))) | AE18: =IF(OR(22<$C18,22>$D18),0,IF(22>=$H18,$I18,IF(22>=$F18,$G18,$E18))) | AF18: =IF(OR(23<$C18,23>$D18),0,IF(23>=$H18,$I18,IF(23>=$F18,$G18,$E18))) | AG18: =IF(OR(24<$C18,24>$D18),0,IF(24>=$H18,$I18,IF(24>=$F18,$G18,$E18))) | AH18: =IF(OR(25<$C18,25>$D18),0,IF(25>=$H18,$I18,IF(25>=$F18,$G18,$E18))) | AI18: =IF(OR(26<$C18,26>$D18),0,IF(26>=$H18,$I18,IF(26>=$F18,$G18,$E18))) | AJ18: =IF(OR(27<$C18,27>$D18),0,IF(27>=$H18,$I18,IF(27>=$F18,$G18,$E18))) | AK18: =IF(OR(28<$C18,28>$D18),0,IF(28>=$H18,$I18,IF(28>=$F18,$G18,$E18))) | AL18: =IF(OR(29<$C18,29>$D18),0,IF(29>=$H18,$I18,IF(29>=$F18,$G18,$E18))) | AM18: =IF(OR(30<$C18,30>$D18),0,IF(30>=$H18,$I18,IF(30>=$F18,$G18,$E18))) | AN18: =IF(OR(31<$C18,31>$D18),0,IF(31>=$H18,$I18,IF(31>=$F18,$G18,$E18))) | AO18: =IF(OR(32<$C18,32>$D18),0,IF(32>=$H18,$I18,IF(32>=$F18,$G18,$E18))) | AP18: =IF(OR(33<$C18,33>$D18),0,IF(33>=$H18,$I18,IF(33>=$F18,$G18,$E18))) | AQ18: =IF(OR(34<$C18,34>$D18),0,IF(34>=$H18,$I18,IF(34>=$F18,$G18,$E18))) | AR18: =IF(OR(35<$C18,35>$D18),0,IF(35>=$H18,$I18,IF(35>=$F18,$G18,$E18))) | AS18: =IF(OR(36<$C18,36>$D18),0,IF(36>=$H18,$I18,IF(36>=$F18,$G18,$E18)))
... B32: Growth analyst | C32: 33 | D32: 999 | E32: 7000 | F32: 999 | G32: 7000 | H32: 999 | I32: 7000 | J32: =IF(OR(1<$C32,1>$D32),0,IF(1>=$H32,$I32,IF(1>=$F32,$G32,$E32))) | K32: =IF(OR(2<$C32,2>$D32),0,IF(2>=$H32,$I32,IF(2>=$F32,$G32,$E32))) | L32: =IF(OR(3<$C32,3>$D32),0,IF(3>=$H32,$I32,IF(3>=$F32,$G32,$E32))) | M32: =IF(OR(4<$C32,4>$D32),0,IF(4>=$H32,$I32,IF(4>=$F32,$G32,$E32))) | N32: =IF(OR(5<$C32,5>$D32),0,IF(5>=$H32,$I32,IF(5>=$F32,$G32,$E32))) | O32: =IF(OR(6<$C32,6>$D32),0,IF(6>=$H32,$I32,IF(6>=$F32,$G32,$E32))) | P32: =IF(OR(7<$C32,7>$D32),0,IF(7>=$H32,$I32,IF(7>=$F32,$G32,$E32))) | Q32: =IF(OR(8<$C32,8>$D32),0,IF(8>=$H32,$I32,IF(8>=$F32,$G32,$E32))) | R32: =IF(OR(9<$C32,9>$D32),0,IF(9>=$H32,$I32,IF(9>=$F32,$G32,$E32))) | S32: =IF(OR(10<$C32,10>$D32),0,IF(10>=$H32,$I32,IF(10>=$F32,$G32,$E32))) | T32: =IF(OR(11<$C32,11>$D32),0,IF(11>=$H32,$I32,IF(11>=$F32,$G32,$E32))) | U32: =IF(OR(12<$C32,12>$D32),0,IF(12>=$H32,$I32,IF(12>=$F32,$G32,$E32))) | V32: =IF(OR(13<$C32,13>$D32),0,IF(13>=$H32,$I32,IF(13>=$F32,$G32,$E32))) | W32: =IF(OR(14<$C32,14>$D32),0,IF(14>=$H32,$I32,IF(14>=$F32,$G32,$E32))) | X32: =IF(OR(15<$C32,15>$D32),0,IF(15>=$H32,$I32,IF(15>=$F32,$G32,$E32))) | Y32: =IF(OR(16<$C32,16>$D32),0,IF(16>=$H32,$I32,IF(16>=$F32,$G32,$E32))) | Z32: =IF(OR(17<$C32,17>$D32),0,IF(17>=$H32,$I32,IF(17>=$F32,$G32,$E32))) | AA32: =IF(OR(18<$C32,18>$D32),0,IF(18>=$H32,$I32,IF(18>=$F32,$G32,$E32))) | AB32: =IF(OR(19<$C32,19>$D32),0,IF(19>=$H32,$I32,IF(19>=$F32,$G32,$E32))) | AC32: =IF(OR(20<$C32,20>$D32),0,IF(20>=$H32,$I32,IF(20>=$F32,$G32,$E32))) | AD32: =IF(OR(21<$C32,21>$D32),0,IF(21>=$H32,$I32,IF(21>=$F32,$G32,$E32))) | AE32: =IF(OR(22<$C32,22>$D32),0,IF(22>=$H32,$I32,IF(22>=$F32,$G32,$E32))) | AF32: =IF(OR(23<$C32,23>$D32),0,IF(23>=$H32,$I32,IF(23>=$F32,$G32,$E32))) | AG32: =IF(OR(24<$C32,24>$D32),0,IF(24>=$H32,$I32,IF(24>=$F32,$G32,$E32))) | AH32: =IF(OR(25<$C32,25>$D32),0,IF(25>=$H32,$I32,IF(25>=$F32,$G32,$E32))) | AI32: =IF(OR(26<$C32,26>$D32),0,IF(26>=$H32,$I32,IF(26>=$F32,$G32,$E32))) | AJ32: =IF(OR(27<$C32,27>$D32),0,IF(27>=$H32,$I32,IF(27>=$F32,$G32,$E32))) | AK32: =IF(OR(28<$C32,28>$D32),0,IF(28>=$H32,$I32,IF(28>=$F32,$G32,$E32))) | AL32: =IF(OR(29<$C32,29>$D32),0,IF(29>=$H32,$I32,IF(29>=$F32,$G32,$E32))) | AM32: =IF(OR(30<$C32,30>$D32),0,IF(30>=$H32,$I32,IF(30>=$F32,$G32,$E32))) | AN32: =IF(OR(31<$C32,31>$D32),0,IF(31>=$H32,$I32,IF(31>=$F32,$G32,$E32))) | AO32: =IF(OR(32<$C32,32>$D32),0,IF(32>=$H32,$I32,IF(32>=$F32,$G32,$E32))) | AP32: =IF(OR(33<$C32,33>$D32),0,IF(33>=$H32,$I32,IF(33>=$F32,$G32,$E32))) | AQ32: =IF(OR(34<$C32,34>$D32),0,IF(34>=$H32,$I32,IF(34>=$F32,$G32,$E32))) | AR32: =IF(OR(35<$C32,35>$D32),0,IF(35>=$H32,$I32,IF(35>=$F32,$G32,$E32))) | AS32: =IF(OR(36<$C32,36>$D32),0,IF(36>=$H32,$I32,IF(36>=$F32,$G32,$E32)))
B34: Total personnel cost | J34: =SUM(J7:J32) | K34: =SUM(K7:K32) | L34: =SUM(L7:L32) | M34: =SUM(M7:M32) | N34: =SUM(N7:N32) | O34: =SUM(O7:O32) | P34: =SUM(P7:P32) | Q34: =SUM(Q7:Q32) | ... AS34: =SUM(AS7:AS32)
B35: Headcount | J35: =COUNTIF(J7:J32,">0") | K35: =COUNTIF(K7:K32,">0") | L35: =COUNTIF(L7:L32,">0") | M35: =COUNTIF(M7:M32,">0") | N35: =COUNTIF(N7:N32,">0") | O35: =COUNTIF(O7:O32,">0") | P35: =COUNTIF(P7:P32,">0") | Q35: =COUNTIF(Q7:Q32,">0") | ... AS35: =COUNTIF(AS7:AS32,">0")

Sheet Base
B2: DiaBite — monthly model · Base case
B3: Every figure is a formula reading column D of the Assumptions tab and the Team tab. Change an assumption and this sheet follows. Month 1 is November 2026.
B4: Month | C4: 1 | D4: 2 | E4: 3 | F4: 4 | G4: 5 | H4: 6 | I4: 7 | J4: 8 | K4: 9 | L4: 10 | M4: 11 | N4: 12 | O4: 13 | P4: 14 | Q4: 15 | R4: 16 | S4: 17 | T4: 18 | U4: 19 | V4: 20 | W4: 21 | X4: 22 | Y4: 23 | Z4: 24 | AA4: 25 | AB4: 26 | AC4: 27 | AD4: 28 | AE4: 29 | AF4: 30 | AG4: 31 | AH4: 32 | AI4: 33 | AJ4: 34 | AK4: 35 | AL4: 36
B5: Year | C5: =MIN(3,ROUNDUP(C4/12,0)) | D5: =MIN(3,ROUNDUP(D4/12,0)) | E5: =MIN(3,ROUNDUP(E4/12,0)) | F5: =MIN(3,ROUNDUP(F4/12,0)) | G5: =MIN(3,ROUNDUP(G4/12,0)) | H5: =MIN(3,ROUNDUP(H4/12,0)) | I5: =MIN(3,ROUNDUP(I4/12,0)) | J5: =MIN(3,ROUNDUP(J4/12,0)) | ... AL5: =MIN(3,ROUNDUP(AL4/12,0))
B7: ACQUISITION
B8: Organic signups | C8: =IF(C$4<Assumptions!$D$25,0,Assumptions!$D$26*(1+Assumptions!$D$27)^(C$4-Assumptions!$D$25)) | D8: =IF(D$4<Assumptions!$D$25,0,Assumptions!$D$26*(1+Assumptions!$D$27)^(D$4-Assumptions!$D$25)) | E8: =IF(E$4<Assumptions!$D$25,0,Assumptions!$D$26*(1+Assumptions!$D$27)^(E$4-Assumptions!$D$25)) | F8: =IF(F$4<Assumptions!$D$25,0,Assumptions!$D$26*(1+Assumptions!$D$27)^(F$4-Assumptions!$D$25)) | G8: =IF(G$4<Assumptions!$D$25,0,Assumptions!$D$26*(1+Assumptions!$D$27)^(G$4-Assumptions!$D$25)) | H8: =IF(H$4<Assumptions!$D$25,0,Assumptions!$D$26*(1+Assumptions!$D$27)^(H$4-Assumptions!$D$25)) | I8: =IF(I$4<Assumptions!$D$25,0,Assumptions!$D$26*(1+Assumptions!$D$27)^(I$4-Assumptions!$D$25)) | J8: =IF(J$4<Assumptions!$D$25,0,Assumptions!$D$26*(1+Assumptions!$D$27)^(J$4-Assumptions!$D$25)) | ... AL8: =IF(AL$4<Assumptions!$D$25,0,Assumptions!$D$26*(1+Assumptions!$D$27)^(AL$4-Assumptions!$D$25))
B9: Marketing spend | C9: =INDEX(Assumptions!$D$70:$D$76,MATCH(C$4,Assumptions!$B$70:$B$76,1)) | D9: =INDEX(Assumptions!$D$70:$D$76,MATCH(D$4,Assumptions!$B$70:$B$76,1)) | E9: =INDEX(Assumptions!$D$70:$D$76,MATCH(E$4,Assumptions!$B$70:$B$76,1)) | F9: =INDEX(Assumptions!$D$70:$D$76,MATCH(F$4,Assumptions!$B$70:$B$76,1)) | G9: =INDEX(Assumptions!$D$70:$D$76,MATCH(G$4,Assumptions!$B$70:$B$76,1)) | H9: =INDEX(Assumptions!$D$70:$D$76,MATCH(H$4,Assumptions!$B$70:$B$76,1)) | I9: =INDEX(Assumptions!$D$70:$D$76,MATCH(I$4,Assumptions!$B$70:$B$76,1)) | J9: =INDEX(Assumptions!$D$70:$D$76,MATCH(J$4,Assumptions!$B$70:$B$76,1)) | ... AL9: =INDEX(Assumptions!$D$70:$D$76,MATCH(AL$4,Assumptions!$B$70:$B$76,1))
B10: Cost per registered signup | C10: =INDEX(Assumptions!$D$32:$D$34,C$5) | D10: =INDEX(Assumptions!$D$32:$D$34,D$5) | E10: =INDEX(Assumptions!$D$32:$D$34,E$5) | F10: =INDEX(Assumptions!$D$32:$D$34,F$5) | G10: =INDEX(Assumptions!$D$32:$D$34,G$5) | H10: =INDEX(Assumptions!$D$32:$D$34,H$5) | I10: =INDEX(Assumptions!$D$32:$D$34,I$5) | J10: =INDEX(Assumptions!$D$32:$D$34,J$5) | ... AL10: =INDEX(Assumptions!$D$32:$D$34,AL$5)
B11: Paid signups | C11: =IF(OR(C$4<Assumptions!$D$25,C10=0),0,C9/C10) | D11: =IF(OR(D$4<Assumptions!$D$25,D10=0),0,D9/D10) | E11: =IF(OR(E$4<Assumptions!$D$25,E10=0),0,E9/E10) | F11: =IF(OR(F$4<Assumptions!$D$25,F10=0),0,F9/F10) | G11: =IF(OR(G$4<Assumptions!$D$25,G10=0),0,G9/G10) | H11: =IF(OR(H$4<Assumptions!$D$25,H10=0),0,H9/H10) | I11: =IF(OR(I$4<Assumptions!$D$25,I10=0),0,I9/I10) | J11: =IF(OR(J$4<Assumptions!$D$25,J10=0),0,J9/J10) | ... AL11: =IF(OR(AL$4<Assumptions!$D$25,AL10=0),0,AL9/AL10)
B12: Total registered signups | C12: =C8+C11 | D12: =D8+D11 | E12: =E8+E11 | F12: =F8+F11 | G12: =G8+G11 | H12: =H8+H11 | I12: =I8+I11 | J12: =J8+J11 | ... AL12: =AL8+AL11
B13: Free to paid conversion | C13: =INDEX(Assumptions!$D$37:$D$39,C$5) | D13: =INDEX(Assumptions!$D$37:$D$39,D$5) | E13: =INDEX(Assumptions!$D$37:$D$39,E$5) | F13: =INDEX(Assumptions!$D$37:$D$39,F$5) | G13: =INDEX(Assumptions!$D$37:$D$39,G$5) | H13: =INDEX(Assumptions!$D$37:$D$39,H$5) | I13: =INDEX(Assumptions!$D$37:$D$39,I$5) | J13: =INDEX(Assumptions!$D$37:$D$39,J$5) | ... AL13: =INDEX(Assumptions!$D$37:$D$39,AL$5)
B14: Free users before upgrades | C14: =C12*(1-C13) | D14: =C19*(1-Assumptions!$D$28)+D12*(1-D13) | E14: =D19*(1-Assumptions!$D$28)+E12*(1-E13) | F14: =E19*(1-Assumptions!$D$28)+F12*(1-F13) | G14: =F19*(1-Assumptions!$D$28)+G12*(1-G13) | H14: =G19*(1-Assumptions!$D$28)+H12*(1-H13) | I14: =H19*(1-Assumptions!$D$28)+I12*(1-I13) | J14: =I19*(1-Assumptions!$D$28)+J12*(1-J13) | K14: =J19*(1-Assumptions!$D$28)+K12*(1-K13) | ... AL14: =AK19*(1-Assumptions!$D$28)+AL12*(1-AL13)
B15: Upgrades from the free base | C15: =C14*Assumptions!$D$29 | D15: =D14*Assumptions!$D$29 | E15: =E14*Assumptions!$D$29 | F15: =F14*Assumptions!$D$29 | G15: =G14*Assumptions!$D$29 | H15: =H14*Assumptions!$D$29 | I15: =I14*Assumptions!$D$29 | J15: =J14*Assumptions!$D$29 | ... AL15: =AL14*Assumptions!$D$29
B16: New paying subscribers | C16: =C12*C13+C15 | D16: =D12*D13+D15 | E16: =E12*E13+E15 | F16: =F12*F13+F15 | G16: =G12*G13+G15 | H16: =H12*H13+H15 | I16: =I12*I13+I15 | J16: =J12*J13+J15 | ... AL16: =AL12*AL13+AL15
B18: SUBSCRIBERS, END OF MONTH
B19: Free users | C19: =C14-C15 | D19: =D14-D15 | E19: =E14-E15 | F19: =F14-F15 | G19: =G14-G15 | H19: =H14-H15 | I19: =I14-I15 | J19: =J14-J15 | ... AL19: =AL14-AL15
B20: Monthly-plan subscribers | C20: =C16*Assumptions!$D$13 | D20: =C20*(1-INDEX(Assumptions!$D$42:$D$44,D$5))+D16*Assumptions!$D$13 | E20: =D20*(1-INDEX(Assumptions!$D$42:$D$44,E$5))+E16*Assumptions!$D$13 | F20: =E20*(1-INDEX(Assumptions!$D$42:$D$44,F$5))+F16*Assumptions!$D$13 | G20: =F20*(1-INDEX(Assumptions!$D$42:$D$44,G$5))+G16*Assumptions!$D$13 | H20: =G20*(1-INDEX(Assumptions!$D$42:$D$44,H$5))+H16*Assumptions!$D$13 | I20: =H20*(1-INDEX(Assumptions!$D$42:$D$44,I$5))+I16*Assumptions!$D$13 | J20: =I20*(1-INDEX(Assumptions!$D$42:$D$44,J$5))+J16*Assumptions!$D$13 | K20: =J20*(1-INDEX(Assumptions!$D$42:$D$44,K$5))+K16*Assumptions!$D$13 | ... AL20: =AK20*(1-INDEX(Assumptions!$D$42:$D$44,AL$5))+AL16*Assumptions!$D$13
B21: Annual-plan subscribers | C21: =C16*(1-Assumptions!$D$13) | D21: =C21*(1-(1-INDEX(Assumptions!$D$47:$D$49,D$5))/12)+D16*(1-Assumptions!$D$13) | E21: =D21*(1-(1-INDEX(Assumptions!$D$47:$D$49,E$5))/12)+E16*(1-Assumptions!$D$13) | F21: =E21*(1-(1-INDEX(Assumptions!$D$47:$D$49,F$5))/12)+F16*(1-Assumptions!$D$13) | G21: =F21*(1-(1-INDEX(Assumptions!$D$47:$D$49,G$5))/12)+G16*(1-Assumptions!$D$13) | H21: =G21*(1-(1-INDEX(Assumptions!$D$47:$D$49,H$5))/12)+H16*(1-Assumptions!$D$13) | I21: =H21*(1-(1-INDEX(Assumptions!$D$47:$D$49,I$5))/12)+I16*(1-Assumptions!$D$13) | J21: =I21*(1-(1-INDEX(Assumptions!$D$47:$D$49,J$5))/12)+J16*(1-Assumptions!$D$13) | K21: =J21*(1-(1-INDEX(Assumptions!$D$47:$D$49,K$5))/12)+K16*(1-Assumptions!$D$13) | ... AL21: =AK21*(1-(1-INDEX(Assumptions!$D$47:$D$49,AL$5))/12)+AL16*(1-Assumptions!$D$13)
B22: Total paying subscribers | C22: =C20+C21 | D22: =D20+D21 | E22: =E20+E21 | F22: =F20+F21 | G22: =G20+G21 | H22: =H20+H21 | I22: =I20+I21 | J22: =J20+J21 | ... AL22: =AL20+AL21
B23: Exit ARR | C23: =C26*12 | D23: =D26*12 | E23: =E26*12 | F23: =F26*12 | G23: =G26*12 | H23: =H26*12 | I23: =I26*12 | J23: =J26*12 | ... AL23: =AL26*12
B25: REVENUE AND COST OF GOODS
B26: Revenue | C26: =C20*Assumptions!$D$11+C21*Assumptions!$D$12/12 | D26: =D20*Assumptions!$D$11+D21*Assumptions!$D$12/12 | E26: =E20*Assumptions!$D$11+E21*Assumptions!$D$12/12 | F26: =F20*Assumptions!$D$11+F21*Assumptions!$D$12/12 | G26: =G20*Assumptions!$D$11+G21*Assumptions!$D$12/12 | H26: =H20*Assumptions!$D$11+H21*Assumptions!$D$12/12 | I26: =I20*Assumptions!$D$11+I21*Assumptions!$D$12/12 | J26: =J20*Assumptions!$D$11+J21*Assumptions!$D$12/12 | ... AL26: =AL20*Assumptions!$D$11+AL21*Assumptions!$D$12/12
B27: Inference — paying | C27: =C22*Assumptions!$D$17*Assumptions!$D$16 | D27: =D22*Assumptions!$D$17*Assumptions!$D$16 | E27: =E22*Assumptions!$D$17*Assumptions!$D$16 | F27: =F22*Assumptions!$D$17*Assumptions!$D$16 | G27: =G22*Assumptions!$D$17*Assumptions!$D$16 | H27: =H22*Assumptions!$D$17*Assumptions!$D$16 | I27: =I22*Assumptions!$D$17*Assumptions!$D$16 | J27: =J22*Assumptions!$D$17*Assumptions!$D$16 | ... AL27: =AL22*Assumptions!$D$17*Assumptions!$D$16
B28: Inference — free tier | C28: =C19*Assumptions!$D$18*Assumptions!$D$16 | D28: =D19*Assumptions!$D$18*Assumptions!$D$16 | E28: =E19*Assumptions!$D$18*Assumptions!$D$16 | F28: =F19*Assumptions!$D$18*Assumptions!$D$16 | G28: =G19*Assumptions!$D$18*Assumptions!$D$16 | H28: =H19*Assumptions!$D$18*Assumptions!$D$16 | I28: =I19*Assumptions!$D$18*Assumptions!$D$16 | J28: =J19*Assumptions!$D$18*Assumptions!$D$16 | ... AL28: =AL19*Assumptions!$D$18*Assumptions!$D$16
B29: Hosting | C29: =C22*Assumptions!$D$19 | D29: =D22*Assumptions!$D$19 | E29: =E22*Assumptions!$D$19 | F29: =F22*Assumptions!$D$19 | G29: =G22*Assumptions!$D$19 | H29: =H22*Assumptions!$D$19 | I29: =I22*Assumptions!$D$19 | J29: =J22*Assumptions!$D$19 | ... AL29: =AL22*Assumptions!$D$19
B30: Support | C30: =C22*Assumptions!$D$20 | D30: =D22*Assumptions!$D$20 | E30: =E22*Assumptions!$D$20 | F30: =F22*Assumptions!$D$20 | G30: =G22*Assumptions!$D$20 | H30: =H22*Assumptions!$D$20 | I30: =I22*Assumptions!$D$20 | J30: =J22*Assumptions!$D$20 | ... AL30: =AL22*Assumptions!$D$20
